Workbook

Sheet COBRO 2025
B1: M3 GAS POR M3 DE AGUA | F1: 3.4 | AP1: M3 GAS POR M3 DE AGUA | AT1: 3.4
B2: 2017
B3: TORRE A
C4: ENERO | I4: FEBRERO | O4: MARZO | U4: ABRIL | Z4: MAYO | AE4: JUNIO | AJ4: JULIO | AP4: AGOSTO | AV4: SEPTIEMBRE | BB4: OCTUBRE | BG4: NOVIEMBRE | BL4: DICIEMBRE
B6: APTO | C6: AGUA | E6: GAS | F6: $ AGUA | G6: $GAS | H6: $ TOTAL | I6: AGUA | K6: GAS | L6: $ AGUA | M6: $GAS | N6: $ TOTAL | O6: AGUA | Q6: GAS | R6: $ AGUA | S6: $GAS | T6: $ TOTAL | U6: AGUA | V6: GAS | W6: $ AGUA | X6: $GAS | Y6: $ TOTAL | Z6: AGUA | AA6: GAS | AB6: $ AGUA | AC6: $GAS | AD6: $ TOTAL | AE6: AGUA | AF6: GAS | AG6: $ AGUA | AH6: $GAS | AI6: $ TOTAL | AJ6: AGUA | AK6: GAS | AM6: $ AGUA | AN6: $GAS | AO6: $ TOTAL | AP6: AGUA | AQ6: GAS | AS6: $ AGUA | AT6: $GAS | AU6: $ TOTAL | AV6: AGUA | AW6: GAS | AY6: $ AGUA | AZ6: $GAS | BA6: $ TOTAL | BB6: AGUA | BC6: GAS | BD6: $ AGUA | BE6: $GAS | BF6: $ TOTAL | BG6: AGUA | BH6: GAS | BI6: $ AGUA | BJ6: $GAS | BK6: $ TOTAL | BL6: AGUA | BM6: GAS | BN6: $ AGUA | BO6: $GAS | BP6: $ TOTAL
A7: 2017 TORRE A | B7: 201 | C7: 18 | E7: =+C7*$F$1 -> 61.2 | F7: =+C7*$E$48 -> 128815.26 | G7: =+E7*$E$47 -> #REF! | H7: =+G7+F7 -> #REF! | I7: 18 | K7: =+I7*$F$1 -> 61.2 | L7: =+I7*$K$48 -> 128815.26 | M7: =+K7*$K$47 -> 124200.4 | N7: =+M7+L7 -> 253015.67 | O7: 12 | Q7: =+O7*$F$1 -> 40.8 | R7: =+O7*$Q$48 -> 86022.84 | S7: =+Q7*$Q$47 -> 90173.852 | T7: =+S7+R7 -> 176196.69 | U7: 13 | V7: =+U7*$F$1 -> 44.2 | W7: =+U7*$V$48 -> 93191.41 | X7: =+V7*$V$47 -> 103653.82 | Y7: =+X7+W7 -> 196845.23 | Z7: 10 | AA7: =+Z7*$F$1 -> 34 | AB7: =+Z7*$AB$48 -> 75107.239 | AC7: =+AA7*$AB$47 -> 69931.076 | AD7: =+AC7+AB7 -> 145038.32 | AE7: 14 | AF7: =+AE7*$F$1 -> 47.6 | AG7: =+AE7*$AF$48 -> 105150.13 | AH7: =+AF7*$AF$47 -> 100312.99 | AI7: =+AH7+AG7 -> 205463.12 | AJ7: 12 | AK7: =+AJ7*$F$1 -> 40.8 | AM7: =+AJ7*$AK$48 -> 89128.607 | AN7: =+AK7*$AK$47 -> 87840.312 | AO7: =+AN7+AM7 -> 176968.92 | AP7: 14 | AQ7: =+AP7*$F$1 -> 47.6 | AS7: =+AP7*$AQ$48 -> 103983.37 | AT7: =+AQ7*$AQ$47 -> 98111.487 | AU7: =+AT7+AS7 -> 202094.86 | AV7: 12 | AW7: =+AV7*$F$1 -> 40.8 | AY7: =+AV7*$AW$48 -> 89130.428 | AZ7: =+AW7*$AW$47 -> 95922.437 | BA7: =+AZ7+AY7 -> 185052.87 | BB7: 25 | BC7: =+BB7*$F$1 -> 85 | BD7: =+BB7*$BC$48 -> 185688.39 | BE7: =+BC7*$BC$47 -> 190552.82 | BF7: =+BE7+BD7 -> 376241.21 | BG7: 23 | BH7: =+BG7*$F$1 -> 78.2 | BI7: =+BG7*$BH$48 -> 170842.56 | BJ7: =+BH7*$BH$47 -> 165357.38 | BK7: =+BJ7+BI7 -> 336199.94 | BL7: 26 | BM7: =+BL7*$F$1 -> 88.4 | BN7: =+BL7*$BM$48 -> 193126.38 | BO7: =+BM7*$BM$47 -> 190707.24 | BP7: =+BO7+BN7 -> 383833.62
A8: 2017 TORRE A | B8: 202 | C8: 1 | E8: =+C8*$F$1 -> 3.4 | F8: =+C8*$E$48 -> 7156.4036 | G8: =+E8*$E$47 -> #REF! | H8: =+G8+F8 -> #REF! | I8: 1 | K8: =+I8*$F$1 -> 3.4 | L8: =+I8*$K$48 -> 7156.4036 | M8: =+K8*$K$47 -> 6900.0223 | N8: =+M8+L8 -> 14056.426 | O8: 1 | Q8: =+O8*$F$1 -> 3.4 | R8: =+O8*$Q$48 -> 7168.57 | S8: =+Q8*$Q$47 -> 7514.4877 | T8: =+S8+R8 -> 14683.058 | U8: 1 | V8: =+U8*$F$1 -> 3.4 | W8: =+U8*$V$48 -> 7168.57 | X8: =+V8*$V$47 -> 7973.3711 | Y8: =+X8+W8 -> 15141.941 | Z8: 1 | AA8: =+Z8*$F$1 -> 3.4 | AB8: =+Z8*$AB$48 -> 7510.7239 | AC8: =+AA8*$AB$47 -> 6993.1076 | AD8: =+AC8+AB8 -> 14503.832 | AE8: 0 | AF8: =+AE8*$F$1 -> 0 | AG8: =+AE8*$AF$48 -> 0 | AH8: =+AF8*$AF$47 -> 0 | AI8: =+AH8+AG8 -> 0 | AJ8: 1 | AK8: =+AJ8*$F$1 -> 3.4 | AM8: =+AJ8*$AK$48 -> 7427.3839 | AN8: =+AK8*$AK$47 -> 7320.026 | AO8: =+AN8+AM8 -> 14747.41 | AP8: 1 | AQ8: =+AP8*$F$1 -> 3.4 | AS8: =+AP8*$AQ$48 -> 7427.3839 | AT8: =+AQ8*$AQ$47 -> 7007.9634 | AU8: =+AT8+AS8 -> 14435.347 | AV8: 1 | AW8: =+AV8*$F$1 -> 3.4 | AY8: =+AV8*$AW$48 -> 7427.5357 | AZ8: =+AW8*$AW$47 -> 7993.5364 | BA8: =+AZ8+AY8 -> 15421.072 | BB8: 1 | BC8: =+BB8*$F$1 -> 3.4 | BD8: =+BB8*$BC$48 -> 7427.5357 | BE8: =+BC8*$BC$47 -> 7622.1128 | BF8: =+BE8+BD8 -> 15049.648 | BG8: 1 | BH8: =+BG8*$F$1 -> 3.4 | BI8: =+BG8*$BH$48 -> 7427.9375 | BJ8: =+BH8*$BH$47 -> 7189.4514 | BK8: =+BJ8+BI8 -> 14617.389 | BL8: 1 | BM8: =+BL8*$F$1 -> 3.4 | BN8: =+BL8*$BM$48 -> 7427.9375 | BO8: =+BM8*$BM$47 -> 7334.894 | BP8: =+BO8+BN8 -> 14762.832
A9: 2017 TORRE A | B9: 203 | C9: 0 | E9: =+C9*$F$1 -> 0 | F9: =+C9*$E$48 -> 0 | G9: =+E9*$E$47 -> #REF! | H9: =+G9+F9 -> #REF! | I9: 0 | K9: =+I9*$F$1 -> 0 | L9: =+I9*$K$48 -> 0 | M9: =+K9*$K$47 -> 0 | N9: =+M9+L9 -> 0 | O9: 0 | Q9: =+O9*$F$1 -> 0 | R9: =+O9*$Q$48 -> 0 | S9: =+Q9*$Q$47 -> 0 | T9: =+S9+R9 -> 0 | U9: 0 | V9: =+U9*$F$1 -> 0 | W9: =+U9*$V$48 -> 0 | X9: =+V9*$V$47 -> 0 | Y9: =+X9+W9 -> 0 | Z9: 0 | AA9: =+Z9*$F$1 -> 0 | AB9: =+Z9*$AB$48 -> 0 | AC9: =+AA9*$AB$47 -> 0 | AD9: =+AC9+AB9 -> 0 | AE9: 0 | AF9: =+AE9*$F$1 -> 0 | AG9: =+AE9*$AF$48 -> 0 | AH9: =+AF9*$AF$47 -> 0 | AI9: =+AH9+AG9 -> 0 | AJ9: 0 | AK9: =+AJ9*$F$1 -> 0 | AM9: =+AJ9*$AK$48 -> 0 | AN9: =+AK9*$AK$47 -> 0 | AO9: =+AN9+AM9 -> 0 | AP9: 7 | AQ9: =+AP9*$F$1 -> 23.8 | AS9: =+AP9*$AQ$48 -> 51991.687 | AT9: =+AQ9*$AQ$47 -> 49055.744 | AU9: =+AT9+AS9 -> 101047.43 | AV9: 6 | AW9: =+AV9*$F$1 -> 20.4 | AY9: =+AV9*$AW$48 -> 44565.214 | AZ9: =+AW9*$AW$47 -> 47961.219 | BA9: =+AZ9+AY9 -> 92526.433 | BB9: 8 | BC9: =+BB9*$F$1 -> 27.2 | BD9: =+BB9*$BC$48 -> 59420.285 | BE9: =+BC9*$BC$47 -> 60976.902 | BF9: =+BE9+BD9 -> 120397.19 | BG9: 6 | BH9: =+BG9*$F$1 -> 20.4 | BI9: =+BG9*$BH$48 -> 44567.625 | BJ9: =+BH9*$BH$47 -> 43136.708 | BK9: =+BJ9+BI9 -> 87704.333 | BL9: 7 | BM9: =+BL9*$F$1 -> 23.8 | BN9: =+BL9*$BM$48 -> 51995.562 | BO9: =+BM9*$BM$47 -> 51344.258 | BP9: =+BO9+BN9 -> 103339.82
A10: 2017 TORRE A | B10: 301 | C10: 28 | E10: =+C10*$F$1 -> 95.2 | F10: =+C10*$E$48 -> 200379.3 | G10: =+E10*$E$47 -> #REF! | H10: =+G10+F10 -> #REF! | I10: 22 | K10: =+I10*$F$1 -> 74.8 | L10: =+I10*$K$48 -> 157440.88 | M10: =+K10*$K$47 -> 151800.49 | N10: =+M10+L10 -> 309241.37 | O10: 18 | Q10: =+O10*$F$1 -> 61.2 | R10: =+O10*$Q$48 -> 129034.26 | S10: =+Q10*$Q$47 -> 135260.78 | T10: =+S10+R10 -> 264295.04 | U10: 21 | V10: =+U10*$F$1 -> 71.4 | W10: =+U10*$V$48 -> 150539.97 | X10: =+V10*$V$47 -> 167440.79 | Y10: =+X10+W10 -> 317980.76 | Z10: 15 | AA10: =+Z10*$F$1 -> 51 | AB10: =+Z10*$AB$48 -> 112660.86 | AC10: =+AA10*$AB$47 -> 104896.61 | AD10: =+AC10+AB10 -> 217557.47 | AE10: 17 | AF10: =+AE10*$F$1 -> 57.8 | AG10: =+AE10*$AF$48 -> 127682.31 | AH10: =+AF10*$AF$47 -> 121808.63 | AI10: =+AH10+AG10 -> 249490.94 | AJ10: 18 | AK10: =+AJ10*$F$1 -> 61.2 | AM10: =+AJ10*$AK$48 -> 133692.91 | AN10: =+AK10*$AK$47 -> 131760.47 | AO10: =+AN10+AM10 -> 265453.38 | AP10: 20 | AQ10: =+AP10*$F$1 -> 68 | AS10: =+AP10*$AQ$48 -> 148547.68 | AT10: =+AQ10*$AQ$47 -> 140159.27 | AU10: =+AT10+AS10 -> 288706.95 | AV10: 20 | AW10: =+AV10*$F$1 -> 68 | AY10: =+AV10*$AW$48 -> 148550.71 | AZ10: =+AW10*$AW$47 -> 159870.73 | BA10: =+AZ10+AY10 -> 308421.44 | BB10: 20 | BC10: =+BB10*$F$1 -> 68 | BD10: =+BB10*$BC$48 -> 148550.71 | BE10: =+BC10*$BC$47 -> 152442.26 | BF10: =+BE10+BD10 -> 300992.97 | BG10: 18 | BH10: =+BG10*$F$1 -> 61.2 | BI10: =+BG10*$BH$48 -> 133702.88 | BJ10: =+BH10*$BH$47 -> 129410.12 | BK10: =+BJ10+BI10 -> 263113 | BL10: 18 | BM10: =+BL10*$F$1 -> 61.2 | BN10: =+BL10*$BM$48 -> 133702.88 | BO10: =+BM10*$BM$47 -> 132028.09 | BP10: =+BO10+BN10 -> 265730.97
A11: 2017 TORRE A | B11: 302 | C11: 10 | E11: =+C11*$F$1 -> 34 | F11: =+C11*$E$48 -> 71564.036 | G11: =+E11*$E$47 -> #REF! | H11: =+G11+F11 -> #REF! | I11: 9 | K11: =+I11*$F$1 -> 30.6 | L11: =+I11*$K$48 -> 64407.632 | M11: =+K11*$K$47 -> 62100.2 | N11: =+M11+L11 -> 126507.83 | O11: 10 | Q11: =+O11*$F$1 -> 34 | R11: =+O11*$Q$48 -> 71685.7 | S11: =+Q11*$Q$47 -> 75144.877 | T11: =+S11+R11 -> 146830.58 | U11: 15 | V11: =+U11*$F$1 -> 51 | W11: =+U11*$V$48 -> 107528.55 | X11: =+V11*$V$47 -> 119600.57 | Y11: =+X11+W11 -> 227129.12 | Z11: 12 | AA11: =+Z11*$F$1 -> 40.8 | AB11: =+Z11*$AB$48 -> 90128.687 | AC11: =+AA11*$AB$47 -> 83917.292 | AD11: =+AC11+AB11 -> 174045.98 | AE11: 13 | AF11: =+AE11*$F$1 -> 44.2 | AG11: =+AE11*$AF$48 -> 97639.411 | AH11: =+AF11*$AF$47 -> 93147.776 | AI11: =+AH11+AG11 -> 190787.19 | AJ11: 12 | AK11: =+AJ11*$F$1 -> 40.8 | AM11: =+AJ11*$AK$48 -> 89128.607 | AN11: =+AK11*$AK$47 -> 87840.312 | AO11: =+AN11+AM11 -> 176968.92 | AP11: 13 | AQ11: =+AP11*$F$1 -> 44.2 | AS11: =+AP11*$AQ$48 -> 96555.991 | AT11: =+AQ11*$AQ$47 -> 91103.524 | AU11: =+AT11+AS11 -> 187659.51 | AV11: 14 | AW11: =+AV11*$F$1 -> 47.6 | AY11: =+AV11*$AW$48 -> 103985.5 | AZ11: =+AW11*$AW$47 -> 111909.51 | BA11: =+AZ11+AY11 -> 215895.01 | BB11: 12 | BC11: =+BB11*$F$1 -> 40.8 | BD11: =+BB11*$BC$48 -> 89130.428 | BE11: =+BC11*$BC$47 -> 91465.353 | BF11: =+BE11+BD11 -> 180595.78 | BG11: 13 | BH11: =+BG11*$F$1 -> 44.2 | BI11: =+BG11*$BH$48 -> 96563.188 | BJ11: =+BH11*$BH$47 -> 93462.868 | BK11: =+BJ11+BI11 -> 190026.06 | BL11: 13 | BM11: =+BL11*$F$1 -> 44.2 | BN11: =+BL11*$BM$48 -> 96563.188 | BO11: =+BM11*$BM$47 -> 95353.622 | BP11: =+BO11+BN11 -> 191916.81
A12: 2017 TORRE A | B12: 401 | C12: 5 | E12: =+C12*$F$1 -> 17 | F12: =+C12*$E$48 -> 35782.018 | G12: =+E12*$E$47 -> #REF! | H12: =+G12+F12 -> #REF! | I12: 4 | K12: =+I12*$F$1 -> 13.6 | L12: =+I12*$K$48 -> 28625.614 | M12: =+K12*$K$47 -> 27600.089 | N12: =+M12+L12 -> 56225.703 | O12: 6 | Q12: =+O12*$F$1 -> 20.4 | R12: =+O12*$Q$48 -> 43011.42 | S12: =+Q12*$Q$47 -> 45086.926 | T12: =+S12+R12 -> 88098.346 | U12: 5 | V12: =+U12*$F$1 -> 17 | W12: =+U12*$V$48 -> 35842.85 | X12: =+V12*$V$47 -> 39866.855 | Y12: =+X12+W12 -> 75709.706 | Z12: 4 | AA12: =+Z12*$F$1 -> 13.6 | AB12: =+Z12*$AB$48 -> 30042.896 | AC12: =+AA12*$AB$47 -> 27972.431 | AD12: =+AC12+AB12 -> 58015.326 | AE12: 6 | AF12: =+AE12*$F$1 -> 20.4 | AG12: =+AE12*$AF$48 -> 45064.343 | AH12: =+AF12*$AF$47 -> 42991.281 | AI12: =+AH12+AG12 -> 88055.624 | AJ12: 5 | AK12: =+AJ12*$F$1 -> 17 | AM12: =+AJ12*$AK$48 -> 37136.919 | AN12: =+AK12*$AK$47 -> 36600.13 | AO12: =+AN12+AM12 -> 73737.049 | AP12: 5 | AQ12: =+AP12*$F$1 -> 17 | AS12: =+AP12*$AQ$48 -> 37136.919 | AT12: =+AQ12*$AQ$47 -> 35039.817 | AU12: =+AT12+AS12 -> 72176.736 | AV12: 5 | AW12: =+AV12*$F$1 -> 17 | AY12: =+AV12*$AW$48 -> 37137.678 | AZ12: =+AW12*$AW$47 -> 39967.682 | BA12: =+AZ12+AY12 -> 77105.361 | BB12: 6 | BC12: =+BB12*$F$1 -> 20.4 | BD12: =+BB12*$BC$48 -> 44565.214 | BE12: =+BC12*$BC$47 -> 45732.677 | BF12: =+BE12+BD12 -> 90297.891 | BG12: 4 | BH12: =+BG12*$F$1 -> 13.6 | BI12: =+BG12*$BH$48 -> 29711.75 | BJ12: =+BH12*$BH$47 -> 28757.806 | BK12: =+BJ12+BI12 -> 58469.556 | BL12: 7 | BM12: =+BL12*$F$1 -> 23.8 | BN12: =+BL12*$BM$48 -> 51995.562 | BO12: =+BM12*$BM$47 -> 51344.258 | BP12: =+BO12+BN12 -> 103339.82
A13: 2017 TORRE A | B13: 402 | C13: 3 | E13: =+C13*$F$1 -> 10.2 | F13: =+C13*$E$48 -> 21469.211 | G13: =+E13*$E$47 -> #REF! | H13: =+G13+F13 -> #REF! | I13: 4 | K13: =+I13*$F$1 -> 13.6 | L13: =+I13*$K$48 -> 28625.614 | M13: =+K13*$K$47 -> 27600.089 | N13: =+M13+L13 -> 56225.703 | O13: 3 | Q13: =+O13*$F$1 -> 10.2 | R13: =+O13*$Q$48 -> 21505.71 | S13: =+Q13*$Q$47 -> 22543.463 | T13: =+S13+R13 -> 44049.173 | U13: 4 | V13: =+U13*$F$1 -> 13.6 | W13: =+U13*$V$48 -> 28674.28 | X13: =+V13*$V$47 -> 31893.484 | Y13: =+X13+W13 -> 60567.764 | Z13: 2 | AA13: =+Z13*$F$1 -> 6.8 | AB13: =+Z13*$AB$48 -> 15021.448 | AC13: =+AA13*$AB$47 -> 13986.215 | AD13: =+AC13+AB13 -> 29007.663 | AE13: 3 | AF13: =+AE13*$F$1 -> 10.2 | AG13: =+AE13*$AF$48 -> 22532.172 | AH13: =+AF13*$AF$47 -> 21495.641 | AI13: =+AH13+AG13 -> 44027.812 | AJ13: 3 | AK13: =+AJ13*$F$1 -> 10.2 | AM13: =+AJ13*$AK$48 -> 22282.152 | AN13: =+AK13*$AK$47 -> 21960.078 | AO13: =+AN13+AM13 -> 44242.23 | AP13: 3 | AQ13: =+AP13*$F$1 -> 10.2 | AS13: =+AP13*$AQ$48 -> 22282.152 | AT13: =+AQ13*$AQ$47 -> 21023.89 | AU13: =+AT13+AS13 -> 43306.042 | AV13: 4 | AW13: =+AV13*$F$1 -> 13.6 | AY13: =+AV13*$AW$48 -> 29710.143 | AZ13: =+AW13*$AW$47 -> 31974.146 | BA13: =+AZ13+AY13 -> 61684.288 | BB13: 1 | BC13: =+BB13*$F$1 -> 3.4 | BD13: =+BB13*$BC$48 -> 7427.5357 | BE13: =+BC13*$BC$47 -> 7622.1128 | BF13: =+BE13+BD13 -> 15049.648 | BG13: 2 | BH13: =+BG13*$F$1 -> 6.8 | BI13: =+BG13*$BH$48 -> 14855.875 | BJ13: =+BH13*$BH$47 -> 14378.903 | BK13: =+BJ13+BI13 -> 29234.778 | BL13: 4 | BM13: =+BL13*$F$1 -> 13.6 | BN13: =+BL13*$BM$48 -> 29711.75 | BO13: =+BM13*$BM$47 -> 29339.576 | BP13: =+BO13+BN13 -> 59051.326
A14: 2017 TORRE A | B14: 403 | C14: 1 | E14: =+C14*$F$1 -> 3.4 | F14: =+C14*$E$48 -> 7156.4036 | G14: =+E14*$E$47 -> #REF! | H14: =+G14+F14 -> #REF! | I14: 1 | K14: =+I14*$F$1 -> 3.4 | L14: =+I14*$K$48 -> 7156.4036 | M14: =+K14*$K$47 -> 6900.0223 | N14: =+M14+L14 -> 14056.426 | O14: 1 | Q14: =+O14*$F$1 -> 3.4 | R14: =+O14*$Q$48 -> 7168.57 | S14: =+Q14*$Q$47 -> 7514.4877 | T14: =+S14+R14 -> 14683.058 | U14: 2 | V14: =+U14*$F$1 -> 6.8 | W14: =+U14*$V$48 -> 14337.14 | X14: =+V14*$V$47 -> 15946.742 | Y14: =+X14+W14 -> 30283.882 | Z14: 1 | AA14: =+Z14*$F$1 -> 3.4 | AB14: =+Z14*$AB$48 -> 7510.7239 | AC14: =+AA14*$AB$47 -> 6993.1076 | AD14: =+AC14+AB14 -> 14503.832 | AE14: 1 | AF14: =+AE14*$F$1 -> 3.4 | AG14: =+AE14*$AF$48 -> 7510.7239 | AH14: =+AF14*$AF$47 -> 7165.2135 | AI14: =+AH14+AG14 -> 14675.937 | AJ14: 1 | AK14: =+AJ14*$F$1 -> 3.4 | AM14: =+AJ14*$AK$48 -> 7427.3839 | AN14: =+AK14*$AK$47 -> 7320.026 | AO14: =+AN14+AM14 -> 14747.41 | AP14: 1 | AQ14: =+AP14*$F$1 -> 3.4 | AS14: =+AP14*$AQ$48 -> 7427.3839 | AT14: =+AQ14*$AQ$47 -> 7007.9634 | AU14: =+AT14+AS14 -> 14435.347 | AV14: 1 | AW14: =+AV14*$F$1 -> 3.4 | AY14: =+AV14*$AW$48 -> 7427.5357 | AZ14: =+AW14*$AW$47 -> 7993.5364 | BA14: =+AZ14+AY14 -> 15421.072 | BB14: 2 | BC14: =+BB14*$F$1 -> 6.8 | BD14: =+BB14*$BC$48 -> 14855.071 | BE14: =+BC14*$BC$47 -> 15244.226 | BF14: =+BE14+BD14 -> 30099.297 | BG14: 1 | BH14: =+BG14*$F$1 -> 3.4 | BI14: =+BG14*$BH$48 -> 7427.9375 | BJ14: =+BH14*$BH$47 -> 7189.4514 | BK14: =+BJ14+BI14 -> 14617.389 | BL14: 1 | BM14: =+BL14*$F$1 -> 3.4 | BN14: =+BL14*$BM$48 -> 7427.9375 | BO14: =+BM14*$BM$47 -> 7334.894 | BP14: =+BO14+BN14 -> 14762.832
A15: 2017 TORRE A | B15: 404 | C15: 6 | E15: =+C15*$F$1 -> 20.4 | F15: =+C15*$E$48 -> 42938.421 | G15: =+E15*$E$47 -> #REF! | H15: =+G15+F15 -> #REF! | I15: 5 | K15: =+I15*$F$1 -> 17 | L15: =+I15*$K$48 -> 35782.018 | M15: =+K15*$K$47 -> 34500.111 | N15: =+M15+L15 -> 70282.129 | O15: 7 | Q15: =+O15*$F$1 -> 23.8 | R15: =+O15*$Q$48 -> 50179.99 | S15: =+Q15*$Q$47 -> 52601.414 | T15: =+S15+R15 -> 102781.4 | U15: 6 | V15: =+U15*$F$1 -> 20.4 | W15: =+U15*$V$48 -> 43011.42 | X15: =+V15*$V$47 -> 47840.227 | Y15: =+X15+W15 -> 90851.647 | Z15: 6 | AA15: =+Z15*$F$1 -> 20.4 | AB15: =+Z15*$AB$48 -> 45064.343 | AC15: =+AA15*$AB$47 -> 41958.646 | AD15: =+AC15+AB15 -> 87022.989 | AE15: 7 | AF15: =+AE15*$F$1 -> 23.8 | AG15: =+AE15*$AF$48 -> 52575.067 | AH15: =+AF15*$AF$47 -> 50156.495 | AI15: =+AH15+AG15 -> 102731.56 | AJ15: 7 | AK15: =+AJ15*$F$1 -> 23.8 | AM15: =+AJ15*$AK$48 -> 51991.687 | AN15: =+AK15*$AK$47 -> 51240.182 | AO15: =+AN15+AM15 -> 103231.87 | AP15: 0 | AQ15: =+AP15*$F$1 -> 0 | AS15: =+AP15*$AQ$48 -> 0 | AT15: =+AQ15*$AQ$47 -> 0 | AU15: =+AT15+AS15 -> 0 | AV15: 0 | AW15: =+AV15*$F$1 -> 0 | AY15: =+AV15*$AW$48 -> 0 | AZ15: =+AW15*$AW$47 -> 0 | BA15: =+AZ15+AY15 -> 0 | BB15: 1 | BC15: =+BB15*$F$1 -> 3.4 | BD15: =+BB15*$BC$48 -> 7427.5357 | BE15: =+BC15*$BC$47 -> 7622.1128 | BF15: =+BE15+BD15 -> 15049.648 | BG15: 3 | BH15: =+BG15*$F$1 -> 10.2 | BI15: =+BG15*$BH$48 -> 22283.812 | BJ15: =+BH15*$BH$47 -> 21568.354 | BK15: =+BJ15+BI15 -> 43852.167 | BL15: 2 | BM15: =+BL15*$F$1 -> 6.8 | BN15: =+BL15*$BM$48 -> 14855.875 | BO15: =+BM15*$BM$47 -> 14669.788 | BP15: =+BO15+BN15 -> 29525.663
A16: 2017 TORRE A | B16: 501 | C16: 1 | E16: =+C16*$F$1 -> 3.4 | F16: =+C16*$E$48 -> 7156.4036 | G16: =+E16*$E$47 -> #REF! | H16: =+G16+F16 -> #REF! | I16: 1 | K16: =+I16*$F$1 -> 3.4 | L16: =+I16*$K$48 -> 7156.4036 | M16: =+K16*$K$47 -> 6900.0223 | N16: =+M16+L16 -> 14056.426 | O16: 2 | Q16: =+O16*$F$1 -> 6.8 | R16: =+O16*$Q$48 -> 14337.14 | S16: =+Q16*$Q$47 -> 15028.975 | T16: =+S16+R16 -> 29366.115 | U16: 2 | V16: =+U16*$F$1 -> 6.8 | W16: =+U16*$V$48 -> 14337.14 | X16: =+V16*$V$47 -> 15946.742 | Y16: =+X16+W16 -> 30283.882 | Z16: 2 | AA16: =+Z16*$F$1 -> 6.8 | AB16: =+Z16*$AB$48 -> 15021.448 | AC16: =+AA16*$AB$47 -> 13986.215 | AD16: =+AC16+AB16 -> 29007.663 | AE16: 2 | AF16: =+AE16*$F$1 -> 6.8 | AG16: =+AE16*$AF$48 -> 15021.448 | AH16: =+AF16*$AF$47 -> 14330.427 | AI16: =+AH16+AG16 -> 29351.875 | AJ16: 2 | AK16: =+AJ16*$F$1 -> 6.8 | AM16: =+AJ16*$AK$48 -> 14854.768 | AN16: =+AK16*$AK$47 -> 14640.052 | AO16: =+AN16+AM16 -> 29494.82 | AP16: 1 | AQ16: =+AP16*$F$1 -> 3.4 | AS16: =+AP16*$AQ$48 -> 7427.3839 | AT16: =+AQ16*$AQ$47 -> 7007.9634 | AU16: =+AT16+AS16 -> 14435.347 | AV16: 2 | AW16: =+AV16*$F$1 -> 6.8 | AY16: =+AV16*$AW$48 -> 14855.071 | AZ16: =+AW16*$AW$47 -> 15987.073 | BA16: =+AZ16+AY16 -> 30842.144 | BB16: 2 | BC16: =+BB16*$F$1 -> 6.8 | BD16: =+BB16*$BC$48 -> 14855.071 | BE16: =+BC16*$BC$47 -> 15244.226 | BF16: =+BE16+BD16 -> 30099.297 | BG16: 3 | BH16: =+BG16*$F$1 -> 10.2 | BI16: =+BG16*$BH$48 -> 22283.812 | BJ16: =+BH16*$BH$47 -> 21568.354 | BK16: =+BJ16+BI16 -> 43852.167 | BL16: 2 | BM16: =+BL16*$F$1 -> 6.8 | BN16: =+BL16*$BM$48 -> 14855.875 | BO16: =+BM16*$BM$47 -> 14669.788 | BP16: =+BO16+BN16 -> 29525.663
A17: 2017 TORRE A | B17: 502 | C17: 2 | E17: =+C17*$F$1 -> 6.8 | F17: =+C17*$E$48 -> 14312.807 | G17: =+E17*$E$47 -> #REF! | H17: =+G17+F17 -> #REF! | I17: 2 | K17: =+I17*$F$1 -> 6.8 | L17: =+I17*$K$48 -> 14312.807 | M17: =+K17*$K$47 -> 13800.045 | N17: =+M17+L17 -> 28112.852 | O17: 2 | Q17: =+O17*$F$1 -> 6.8 | R17: =+O17*$Q$48 -> 14337.14 | S17: =+Q17*$Q$47 -> 15028.975 | T17: =+S17+R17 -> 29366.115 | U17: 3 | V17: =+U17*$F$1 -> 10.2 | W17: =+U17*$V$48 -> 21505.71 | X17: =+V17*$V$47 -> 23920.113 | Y17: =+X17+W17 -> 45425.823 | Z17: 2 | AA17: =+Z17*$F$1 -> 6.8 | AB17: =+Z17*$AB$48 -> 15021.448 | AC17: =+AA17*$AB$47 -> 13986.215 | AD17: =+AC17+AB17 -> 29007.663 | AE17: 3 | AF17: =+AE17*$F$1 -> 10.2 | AG17: =+AE17*$AF$48 -> 22532.172 | AH17: =+AF17*$AF$47 -> 21495.641 | AI17: =+AH17+AG17 -> 44027.812 | AJ17: 2 | AK17: =+AJ17*$F$1 -> 6.8 | AM17: =+AJ17*$AK$48 -> 14854.768 | AN17: =+AK17*$AK$47 -> 14640.052 | AO17: =+AN17+AM17 -> 29494.82 | AP17: 2 | AQ17: =+AP17*$F$1 -> 6.8 | AS17: =+AP17*$AQ$48 -> 14854.768 | AT17: =+AQ17*$AQ$47 -> 14015.927 | AU17: =+AT17+AS17 -> 28870.695 | AV17: 1 | AW17: =+AV17*$F$1 -> 3.4 | AY17: =+AV17*$AW$48 -> 7427.5357 | AZ17: =+AW17*$AW$47 -> 7993.5364 | BA17: =+AZ17+AY17 -> 15421.072 | BB17: 3 | BC17: =+BB17*$F$1 -> 10.2 | BD17: =+BB17*$BC$48 -> 22282.607 | BE17: =+BC17*$BC$47 -> 22866.338 | BF17: =+BE17+BD17 -> 45148.945 | BG17: 3 | BH17: =+BG17*$F$1 -> 10.2 | BI17: =+BG17*$BH$48 -> 22283.812 | BJ17: =+BH17*$BH$47 -> 21568.354 | BK17: =+BJ17+BI17 -> 43852.167 | BL17: 3 | BM17: =+BL17*$F$1 -> 10.2 | BN17: =+BL17*$BM$48 -> 22283.812 | BO17: =+BM17*$BM$47 -> 22004.682 | BP17: =+BO17+BN17 -> 44288.495
A18: 2017 TORRE A | B18: 503 | C18: 4 | E18: =+C18*$F$1 -> 13.6 | F18: =+C18*$E$48 -> 28625.614 | G18: =+E18*$E$47 -> #REF! | H18: =+G18+F18 -> #REF! | I18: 5 | K18: =+I18*$F$1 -> 17 | L18: =+I18*$K$48 -> 35782.018 | M18: =+K18*$K$47 -> 34500.111 | N18: =+M18+L18 -> 70282.129 | O18: 5 | Q18: =+O18*$F$1 -> 17 | R18: =+O18*$Q$48 -> 35842.85 | S18: =+Q18*$Q$47 -> 37572.438 | T18: =+S18+R18 -> 73415.289 | U18: 7 | V18: =+U18*$F$1 -> 23.8 | W18: =+U18*$V$48 -> 50179.99 | X18: =+V18*$V$47 -> 55813.598 | Y18: =+X18+W18 -> 105993.59 | Z18: 5 | AA18: =+Z18*$F$1 -> 17 | AB18: =+Z18*$AB$48 -> 37553.619 | AC18: =+AA18*$AB$47 -> 34965.538 | AD18: =+AC18+AB18 -> 72519.158 | AE18: 5 | AF18: =+AE18*$F$1 -> 17 | AG18: =+AE18*$AF$48 -> 37553.619 | AH18: =+AF18*$AF$47 -> 35826.068 | AI18: =+AH18+AG18 -> 73379.687 | AJ18: 5 | AK18: =+AJ18*$F$1 -> 17 | AM18: =+AJ18*$AK$48 -> 37136.919 | AN18: =+AK18*$AK$47 -> 36600.13 | AO18: =+AN18+AM18 -> 73737.049 | AP18: 3 | AQ18: =+AP18*$F$1 -> 10.2 | AS18: =+AP18*$AQ$48 -> 22282.152 | AT18: =+AQ18*$AQ$47 -> 21023.89 | AU18: =+AT18+AS18 -> 43306.042 | AV18: 4 | AW18: =+AV18*$F$1 -> 13.6 | AY18: =+AV18*$AW$48 -> 29710.143 | AZ18: =+AW18*$AW$47 -> 31974.146 | BA18: =+AZ18+AY18 -> 61684.288 | BB18: 6 | BC18: =+BB18*$F$1 -> 20.4 | BD18: =+BB18*$BC$48 -> 44565.214 | BE18: =+BC18*$BC$47 -> 45732.677 | BF18: =+BE18+BD18 -> 90297.891 | BG18: 4 | BH18: =+BG18*$F$1 -> 13.6 | BI18: =+BG18*$BH$48 -> 29711.75 | BJ18: =+BH18*$BH$47 -> 28757.806 | BK18: =+BJ18+BI18 -> 58469.556 | BL18: 4 | BM18: =+BL18*$F$1 -> 13.6 | BN18: =+BL18*$BM$48 -> 29711.75 | BO18: =+BM18*$BM$47 -> 29339.576 | BP18: =+BO18+BN18 -> 59051.326
... A43: 2017 TORRE A | B43: 1302 | C43: 3 | E43: =+C43*$F$1 -> 10.2 | F43: =+C43*$E$48 -> 21469.211 | G43: =+E43*$E$47 -> #REF! | H43: =+G43+F43 -> #REF! | I43: 6 | K43: =+I43*$F$1 -> 20.4 | L43: =+I43*$K$48 -> 42938.421 | M43: =+K43*$K$47 -> 41400.134 | N43: =+M43+L43 -> 84338.555 | O43: 11 | Q43: =+O43*$F$1 -> 37.4 | R43: =+O43*$Q$48 -> 78854.27 | S43: =+Q43*$Q$47 -> 82659.364 | T43: =+S43+R43 -> 161513.63 | U43: 14 | V43: =+U43*$F$1 -> 47.6 | W43: =+U43*$V$48 -> 100359.98 | X43: =+V43*$V$47 -> 111627.2 | Y43: =+X43+W43 -> 211987.18 | Z43: 11 | AA43: =+Z43*$F$1 -> 37.4 | AB43: =+Z43*$AB$48 -> 82617.963 | AC43: =+AA43*$AB$47 -> 76924.184 | AD43: =+AC43+AB43 -> 159542.15 | AE43: 13 | AF43: =+AE43*$F$1 -> 44.2 | AG43: =+AE43*$AF$48 -> 97639.411 | AH43: =+AF43*$AF$47 -> 93147.776 | AI43: =+AH43+AG43 -> 190787.19 | AJ43: 8 | AK43: =+AJ43*$F$1 -> 27.2 | AM43: =+AJ43*$AK$48 -> 59419.071 | AN43: =+AK43*$AK$47 -> 58560.208 | AO43: =+AN43+AM43 -> 117979.28 | AP43: 11 | AQ43: =+AP43*$F$1 -> 37.4 | AS43: =+AP43*$AQ$48 -> 81701.223 | AT43: =+AQ43*$AQ$47 -> 77087.597 | AU43: =+AT43+AS43 -> 158788.82 | AV43: 14 | AW43: =+AV43*$F$1 -> 47.6 | AY43: =+AV43*$AW$48 -> 103985.5 | AZ43: =+AW43*$AW$47 -> 111909.51 | BA43: =+AZ43+AY43 -> 215895.01 | BB43: 16 | BC43: =+BB43*$F$1 -> 54.4 | BD43: =+BB43*$BC$48 -> 118840.57 | BE43: =+BC43*$BC$47 -> 121953.8 | BF43: =+BE43+BD43 -> 240794.38 | BG43: 9 | BH43: =+BG43*$F$1 -> 30.6 | BI43: =+BG43*$BH$48 -> 66851.438 | BJ43: =+BH43*$BH$47 -> 64705.062 | BK43: =+BJ43+BI43 -> 131556.5 | BL43: 14 | BM43: =+BL43*$F$1 -> 47.6 | BN43: =+BL43*$BM$48 -> 103991.12 | BO43: =+BM43*$BM$47 -> 102688.52 | BP43: =+BO43+BN43 -> 206679.64
A44: 2017 TORRE A | C44: =SUM(C7:C43) -> 186 | E44: =SUM(E7:E43) -> 632.4 | F44: =SUM(F7:F43) -> 1331091.1 | G44: =SUM(G7:G43) -> #REF! | H44: =SUM(H7:H43) -> #REF! | I44: =SUM(I7:I43) -> 183 | K44: =SUM(K7:K43) -> 622.2 | L44: =SUM(L7:L43) -> 1309621.9 | M44: =SUM(M7:M43) -> 1262704.1 | N44: =SUM(N7:N43) -> 2572325.9 | O44: =SUM(O7:O43) -> 187 | Q44: =SUM(Q7:Q43) -> 635.8 | R44: =SUM(R7:R43) -> 1340522.6 | S44: =SUM(S7:S43) -> 1405209.2 | T44: =SUM(T7:T43) -> 2745731.8 | U44: =SUM(U7:U43) -> 231 | V44: =SUM(V7:V43) -> 785.4 | W44: =SUM(W7:W43) -> 1655939.7 | X44: =SUM(X7:X43) -> 1841848.7 | ... AK44: =SUM(AK7:AK43) -> 686.8 | AM44: =SUM(AM7:AM43) -> 1500331.5 | AN44: =SUM(AN7:AN43) -> 1478645.3 | AO44: =SUM(AO7:AO43) -> 2978976.8 | AP44: =SUM(AP7:AP43) -> 195 | AQ44: =SUM(AQ7:AQ43) -> 663 | AS44: =SUM(AS7:AS43) -> 1448339.9 | AT44: =SUM(AT7:AT43) -> 1366552.9 | AU44: =SUM(AU7:AU43) -> 2814892.7 | AV44: =SUM(AV7:AV43) -> 238 | AW44: =SUM(AW7:AW43) -> 809.2 | AY44: =SUM(AY7:AY43) -> 1767753.5 | AZ44: =SUM(AZ7:AZ43) -> 1902461.7 | BA44: =SUM(BA7:BA43) -> 3670215.2 | BB44: =SUM(BB7:BB43) -> 267 | BC44: =SUM(BC7:BC43) -> 907.8 | BD44: =SUM(BD7:BD43) -> 1983152 | BE44: =SUM(BE7:BE43) -> 2035104.1 | BF44: =SUM(BF7:BF43) -> 4018256.1 | ... BP44: =SUM(BP7:BP43) -> 3749759.2
A45: 2017 TORRE A
A46: 2017 TORRE A | C46: ENERO DE 2017 | I46: FEBRERO DE 2017 | O46: MARZO DE 2017 | U46: ABRIL DE 2017 | AA46: MAYO DE 2017 | AE46: JUNIO DE 2017 | AJ46: JULIO DE 2017 | AP46: AGOSTO DE 2017 | AV46: SEPTIEMBRE DE 2017 | BB46: OCTUBRE DE 2017 | BG46: NOVIEMBRE DE 2017 | BL46: DICIEMBRE DE 2017
A47: 2017 TORRE A | C47: VR M3 GAS | E47: =+'Vr M3 DE GAS'!#REF! -> #REF! | I47: VR M3 GAS | K47: =+'Vr M3 DE GAS'!$F$62 -> 2029.4183 | O47: VR M3 GAS | Q47: =+'Vr M3 DE GAS'!$F$63 -> 2210.1434 | U47: VR M3 GAS | V47: =+'Vr M3 DE GAS'!$F$64 -> 2345.1091 | AA47: VR M3 GAS | AB47: =+'Vr M3 DE GAS'!$F$65 -> 2056.7964 | AE47: VR M3 GAS | AF47: =+'Vr M3 DE GAS'!$F$66 -> 2107.4157 | AJ47: VR M3 GAS | AK47: =+'Vr M3 DE GAS'!$F$67 -> 2152.9488 | AP47: VR M3 GAS | AQ47: =+'Vr M3 DE GAS'!$F$68 -> 2061.1657 | AV47: VR M3 GAS | AW47: =+'Vr M3 DE GAS'!$F$69 -> 2351.0401 | BB47: VR M3 GAS | BC47: =+'Vr M3 DE GAS'!$F$70 -> 2241.7979 | BG47: VR M3 GAS | BH47: =+'Vr M3 DE GAS'!$F$71 -> 2114.5445 | BL47: VR M3 GAS | BM47: =+'Vr M3 DE GAS'!$F$72 -> 2157.3218
A48: 2017 TORRE A | C48: VR M3 AGUA | E48: =+'Vr M3 DE AGUA'!$N$4 -> 7156.4036 | I48: VR M3 AGUA | K48: =+'Vr M3 DE AGUA'!$N$4 -> 7156.4036 | O48: VR M3 AGUA | Q48: =+'Vr M3 DE AGUA'!$N$5 -> 7168.57 | U48: VR M3 AGUA | V48: =+'Vr M3 DE AGUA'!$N$5 -> 7168.57 | AA48: VR M3 AGUA | AB48: =+'Vr M3 DE AGUA'!$N$6 -> 7510.7239 | AE48: VR M3 AGUA | AF48: =+'Vr M3 DE AGUA'!$N$6 -> 7510.7239 | AJ48: VR M3 AGUA | AK48: =+'Vr M3 DE AGUA'!$N$7 -> 7427.3839 | AP48: VR M3 AGUA | AQ48: =+'Vr M3 DE AGUA'!$N$7 -> 7427.3839 | AV48: VR M3 AGUA | AW48: =+'Vr M3 DE AGUA'!$N$8 -> 7427.5357 | BB48: VR M3 AGUA | BC48: =+'Vr M3 DE AGUA'!$N$8 -> 7427.5357 | BG48: VR M3 AGUA | BH48: =+'Vr M3 DE AGUA'!N$9 -> 7427.9375 | BL48: VR M3 AGUA | BM48: =+'Vr M3 DE AGUA'!$N$9 -> 7427.9375
B52: AÑO 2017
B53: TORRE B
C54: ENERO | I54: FEBRERO | O54: MARZO | U54: ABRIL | Z54: MAYO | AE54: JUNIO | AJ54: JULIO | AP54: AGOSTO | AV54: SEPTIEMBRE | BB54: OCTUBRE | BG54: NOVIEMBRE | BL54: DICIEMBRE
C56: AGUA | E56: GAS | F56: $ AGUA | G56: $GAS | H56: $ TOTAL | I56: AGUA | K56: GAS | L56: $ AGUA | M56: $GAS | N56: $ TOTAL | O56: AGUA | Q56: GAS | R56: $ AGUA | S56: $GAS | T56: $ TOTAL | U56: AGUA | V56: GAS | W56: $ AGUA | X56: $GAS | Y56: $ TOTAL | Z56: AGUA | AA56: GAS | AB56: $ AGUA | AC56: $GAS | AD56: $ TOTAL | AE56: AGUA | AF56: GAS | AG56: $ AGUA | AH56: $GAS | AI56: $ TOTAL | AJ56: AGUA | AK56: GAS | AM56: $ AGUA | AN56: $GAS | AO56: $ TOTAL | AP56: AGUA | AQ56: GAS | AS56: $ AGUA | AT56: $GAS | AU56: $ TOTAL | AV56: AGUA | AW56: GAS | AY56: $ AGUA | AZ56: $GAS | BA56: $ TOTAL | BB56: AGUA | BC56: GAS | BD56: $ AGUA | BE56: $GAS | BF56: $ TOTAL | BG56: AGUA | BH56: GAS | BI56: $ AGUA | BJ56: $GAS | BK56: $ TOTAL | BL56: AGUA | BM56: GAS | BN56: $ AGUA | BO56: $GAS | BP56: $ TOTAL
A57: 2017 TORRE B | B57: 201 | C57: 5 | E57: =+C57*3 -> 15 | F57: =+C57*$E$93 -> 35782.018 | G57: =+E57*E$92 -> #REF! | H57: =+F57+G57 -> #REF! | I57: 6 | K57: =+I57*$F$1 -> 20.4 | L57: =+I57*$K$93 -> 42938.421 | M57: =+K57*$K$92 -> 41400.134 | N57: =+M57+L57 -> 84338.555 | O57: 6 | Q57: =+O57*$F$1 -> 20.4 | R57: =+O57*$Q$93 -> 43011.42 | S57: =+Q57*$Q$92 -> 45086.926 | T57: =+S57+R57 -> 88098.346 | U57: 6 | V57: =+U57*$F$1 -> 20.4 | W57: =+U57*$V$93 -> 43011.42 | X57: =+V57*$V$92 -> 47840.227 | Y57: =+X57+W57 -> 90851.647 | Z57: 6 | AA57: =+Z57*$F$1 -> 20.4 | AB57: =+Z57*$AB$93 -> 45064.343 | AC57: =+AA57*$AB$92 -> 41958.646 | AD57: =+AC57+AB57 -> 87022.989 | AE57: 8 | AF57: =+AE57*$F$1 -> 27.2 | AG57: =+AE57*$AF$93 -> 60085.791 | AH57: =+AF57*$AF$92 -> 57321.708 | AI57: =+AH57+AG57 -> 117407.5 | AJ57: 5 | AK57: =+AJ57*$F$1 -> 17 | AM57: =+AJ57*$AK$93 -> 37136.919 | AN57: =+AK57*$AK$92 -> 36600.13 | AO57: =+AM57+AN57 -> 73737.049 | AP57: 7 | AQ57: =+AP57*$F$1 -> 23.8 | AS57: =+AP57*$AQ$93 -> 51991.687 | AT57: =+AQ57*$AQ$92 -> 49055.744 | AU57: =+AS57+AT57 -> 101047.43 | AV57: 8 | AW57: =+AV57*$F$1 -> 27.2 | AY57: =+AV57*$AW$93 -> 59420.285 | AZ57: =+AW57*$AW$92 -> 63948.291 | BA57: =+AY57+AZ57 -> 123368.58 | BB57: 7 | BC57: =+BB57*$F$1 -> 23.8 | BD57: =+BB57*$BC$93 -> 51992.75 | BE57: =+BC57*$BC$92 -> 53354.789 | BF57: =+BD57+BE57 -> 105347.54 | BG57: 8 | BH57: =+BG57*$F$1 -> 27.2 | BI57: =+BG57*$BH$93 -> 59423.5 | BJ57: =+BH57*$BH$92 -> 57515.611 | BK57: =+BJ57+BI57 -> 116939.11 | BL57: 9 | BM57: =+BL57*$F$1 -> 30.6 | BN57: =+BL57*$BM$93 -> 66851.438 | BO57: =+BM57*$BM$92 -> 66014.046 | BP57: =+BN57+BO57 -> 132865.48
A58: 2017 TORRE B | B58: 202 | C58: 5 | E58: =+C58*3 -> 15 | F58: =+C58*$E$93 -> 35782.018 | G58: =+E58*E$92 -> #REF! | H58: =+F58+G58 -> #REF! | I58: 5 | K58: =+I58*$F$1 -> 17 | L58: =+I58*$K$93 -> 35782.018 | M58: =+K58*$K$92 -> 34500.111 | N58: =+M58+L58 -> 70282.129 | O58: 5 | Q58: =+O58*$F$1 -> 17 | R58: =+O58*$Q$93 -> 35842.85 | S58: =+Q58*$Q$92 -> 37572.438 | T58: =+S58+R58 -> 73415.289 | U58: 4 | V58: =+U58*$F$1 -> 13.6 | W58: =+U58*$V$93 -> 28674.28 | X58: =+V58*$V$92 -> 31893.484 | Y58: =+X58+W58 -> 60567.764 | Z58: 4 | AA58: =+Z58*$F$1 -> 13.6 | AB58: =+Z58*$AB$93 -> 30042.896 | AC58: =+AA58*$AB$92 -> 27972.431 | AD58: =+AC58+AB58 -> 58015.326 | AE58: 5 | AF58: =+AE58*$F$1 -> 17 | AG58: =+AE58*$AF$93 -> 37553.619 | AH58: =+AF58*$AF$92 -> 35826.068 | AI58: =+AH58+AG58 -> 73379.687 | AJ58: 5 | AK58: =+AJ58*$F$1 -> 17 | AM58: =+AJ58*$AK$93 -> 37136.919 | AN58: =+AK58*$AK$92 -> 36600.13 | AO58: =+AM58+AN58 -> 73737.049 | AP58: 5 | AQ58: =+AP58*$F$1 -> 17 | AS58: =+AP58*$AQ$93 -> 37136.919 | AT58: =+AQ58*$AQ$92 -> 35039.817 | AU58: =+AS58+AT58 -> 72176.736 | AV58: 5 | AW58: =+AV58*$F$1 -> 17 | AY58: =+AV58*$AW$93 -> 37137.678 | AZ58: =+AW58*$AW$92 -> 39967.682 | BA58: =+AY58+AZ58 -> 77105.361 | BB58: 4 | BC58: =+BB58*$F$1 -> 13.6 | BD58: =+BB58*$BC$93 -> 29710.143 | BE58: =+BC58*$BC$92 -> 30488.451 | BF58: =+BD58+BE58 -> 60198.594 | BG58: 3 | BH58: =+BG58*$F$1 -> 10.2 | BI58: =+BG58*$BH$93 -> 22283.812 | BJ58: =+BH58*$BH$92 -> 21568.354 | BK58: =+BJ58+BI58 -> 43852.167 | BL58: 6 | BM58: =+BL58*$F$1 -> 20.4 | BN58: =+BL58*$BM$93 -> 44567.625 | BO58: =+BM58*$BM$92 -> 44009.364 | BP58: =+BN58+BO58 -> 88576.989
A59: 2017 TORRE B | B59: 203 | C59: 4 | E59: =+C59*3 -> 12 | F59: =+C59*$E$93 -> 28625.614 | G59: =+E59*E$92 -> #REF! | H59: =+F59+G59 -> #REF! | I59: 6 | K59: =+I59*$F$1 -> 20.4 | L59: =+I59*$K$93 -> 42938.421 | M59: =+K59*$K$92 -> 41400.134 | N59: =+M59+L59 -> 84338.555 | O59: 6 | Q59: =+O59*$F$1 -> 20.4 | R59: =+O59*$Q$93 -> 43011.42 | S59: =+Q59*$Q$92 -> 45086.926 | T59: =+S59+R59 -> 88098.346 | U59: 6 | V59: =+U59*$F$1 -> 20.4 | W59: =+U59*$V$93 -> 43011.42 | X59: =+V59*$V$92 -> 47840.227 | Y59: =+X59+W59 -> 90851.647 | Z59: 4 | AA59: =+Z59*$F$1 -> 13.6 | AB59: =+Z59*$AB$93 -> 30042.896 | AC59: =+AA59*$AB$92 -> 27972.431 | AD59: =+AC59+AB59 -> 58015.326 | AE59: 5 | AF59: =+AE59*$F$1 -> 17 | AG59: =+AE59*$AF$93 -> 37553.619 | AH59: =+AF59*$AF$92 -> 35826.068 | AI59: =+AH59+AG59 -> 73379.687 | AJ59: 3 | AK59: =+AJ59*$F$1 -> 10.2 | AM59: =+AJ59*$AK$93 -> 22282.152 | AN59: =+AK59*$AK$92 -> 21960.078 | AO59: =+AM59+AN59 -> 44242.23 | AP59: 3 | AQ59: =+AP59*$F$1 -> 10.2 | AS59: =+AP59*$AQ$93 -> 22282.152 | AT59: =+AQ59*$AQ$92 -> 21023.89 | AU59: =+AS59+AT59 -> 43306.042 | AV59: 5 | AW59: =+AV59*$F$1 -> 17 | AY59: =+AV59*$AW$93 -> 37137.678 | AZ59: =+AW59*$AW$92 -> 39967.682 | BA59: =+AY59+AZ59 -> 77105.361 | BB59: 4 | BC59: =+BB59*$F$1 -> 13.6 | BD59: =+BB59*$BC$93 -> 29710.143 | BE59: =+BC59*$BC$92 -> 30488.451 | BF59: =+BD59+BE59 -> 60198.594 | BG59: 5 | BH59: =+BG59*$F$1 -> 17 | BI59: =+BG59*$BH$93 -> 37139.688 | BJ59: =+BH59*$BH$92 -> 35947.257 | BK59: =+BJ59+BI59 -> 73086.944 | BL59: 5 | BM59: =+BL59*$F$1 -> 17 | BN59: =+BL59*$BM$93 -> 37139.688 | BO59: =+BM59*$BM$92 -> 36674.47 | BP59: =+BN59+BO59 -> 73814.158
A60: 2017 TORRE B | B60: 204 | C60: 0 | E60: =+C60*3 -> 0 | F60: =+C60*$E$93 -> 0 | G60: =+E60*E$92 -> #REF! | H60: =+F60+G60 -> #REF! | I60: 1 | K60: =+I60*$F$1 -> 3.4 | L60: =+I60*$K$93 -> 7156.4036 | M60: =+K60*$K$92 -> 6900.0223 | N60: =+M60+L60 -> 14056.426 | O60: 0 | Q60: =+O60*$F$1 -> 0 | R60: =+O60*$Q$93 -> 0 | S60: =+Q60*$Q$92 -> 0 | T60: =+S60+R60 -> 0 | U60: 1 | V60: =+U60*$F$1 -> 3.4 | W60: =+U60*$V$93 -> 7168.57 | X60: =+V60*$V$92 -> 7973.3711 | Y60: =+X60+W60 -> 15141.941 | Z60: 1 | AA60: =+Z60*$F$1 -> 3.4 | AB60: =+Z60*$AB$93 -> 7510.7239 | AC60: =+AA60*$AB$92 -> 6993.1076 | AD60: =+AC60+AB60 -> 14503.832 | AE60: 0 | AF60: =+AE60*$F$1 -> 0 | AG60: =+AE60*$AF$93 -> 0 | AH60: =+AF60*$AF$92 -> 0 | AI60: =+AH60+AG60 -> 0 | AJ60: 1 | AK60: =+AJ60*$F$1 -> 3.4 | AM60: =+AJ60*$AK$93 -> 7427.3839 | AN60: =+AK60*$AK$92 -> 7320.026 | AO60: =+AM60+AN60 -> 14747.41 | AP60: 0 | AQ60: =+AP60*$F$1 -> 0 | AS60: =+AP60*$AQ$93 -> 0 | AT60: =+AQ60*$AQ$92 -> 0 | AU60: =+AS60+AT60 -> 0 | AV60: 1 | AW60: =+AV60*$F$1 -> 3.4 | AY60: =+AV60*$AW$93 -> 7427.5357 | AZ60: =+AW60*$AW$92 -> 7993.5364 | BA60: =+AY60+AZ60 -> 15421.072 | BB60: 0 | BC60: =+BB60*$F$1 -> 0 | BD60: =+BB60*$BC$93 -> 0 | BE60: =+BC60*$BC$92 -> 0 | BF60: =+BD60+BE60 -> 0 | BG60: 0 | BH60: =+BG60*$F$1 -> 0 | BI60: =+BG60*$BH$93 -> 0 | BJ60: =+BH60*$BH$92 -> 0 | BK60: =+BJ60+BI60 -> 0 | BL60: 1 | BM60: =+BL60*$F$1 -> 3.4 | BN60: =+BL60*$BM$93 -> 7427.9375 | BO60: =+BM60*$BM$92 -> 7334.894 | BP60: =+BN60+BO60 -> 14762.832
A61: 2017 TORRE B | B61: 301 | C61: 5 | E61: =+C61*3 -> 15 | F61: =+C61*$E$93 -> 35782.018 | G61: =+E61*E$92 -> #REF! | H61: =+F61+G61 -> #REF! | I61: 5 | K61: =+I61*$F$1 -> 17 | L61: =+I61*$K$93 -> 35782.018 | M61: =+K61*$K$92 -> 34500.111 | N61: =+M61+L61 -> 70282.129 | O61: 4 | Q61: =+O61*$F$1 -> 13.6 | R61: =+O61*$Q$93 -> 28674.28 | S61: =+Q61*$Q$92 -> 30057.951 | T61: =+S61+R61 -> 58732.231 | U61: 6 | V61: =+U61*$F$1 -> 20.4 | W61: =+U61*$V$93 -> 43011.42 | X61: =+V61*$V$92 -> 47840.227 | Y61: =+X61+W61 -> 90851.647 | Z61: 4 | AA61: =+Z61*$F$1 -> 13.6 | AB61: =+Z61*$AB$93 -> 30042.896 | AC61: =+AA61*$AB$92 -> 27972.431 | AD61: =+AC61+AB61 -> 58015.326 | AE61: 5 | AF61: =+AE61*$F$1 -> 17 | AG61: =+AE61*$AF$93 -> 37553.619 | AH61: =+AF61*$AF$92 -> 35826.068 | AI61: =+AH61+AG61 -> 73379.687 | AJ61: 3 | AK61: =+AJ61*$F$1 -> 10.2 | AM61: =+AJ61*$AK$93 -> 22282.152 | AN61: =+AK61*$AK$92 -> 21960.078 | AO61: =+AM61+AN61 -> 44242.23 | AP61: 5 | AQ61: =+AP61*$F$1 -> 17 | AS61: =+AP61*$AQ$93 -> 37136.919 | AT61: =+AQ61*$AQ$92 -> 35039.817 | AU61: =+AS61+AT61 -> 72176.736 | AV61: 7 | AW61: =+AV61*$F$1 -> 23.8 | AY61: =+AV61*$AW$93 -> 51992.75 | AZ61: =+AW61*$AW$92 -> 55954.755 | BA61: =+AY61+AZ61 -> 107947.5 | BB61: 6 | BC61: =+BB61*$F$1 -> 20.4 | BD61: =+BB61*$BC$93 -> 44565.214 | BE61: =+BC61*$BC$92 -> 45732.677 | BF61: =+BD61+BE61 -> 90297.891 | BG61: 7 | BH61: =+BG61*$F$1 -> 23.8 | BI61: =+BG61*$BH$93 -> 51995.562 | BJ61: =+BH61*$BH$92 -> 50326.16 | BK61: =+BJ61+BI61 -> 102321.72 | BL61: 8 | BM61: =+BL61*$F$1 -> 27.2 | BN61: =+BL61*$BM$93 -> 59423.5 | BO61: =+BM61*$BM$92 -> 58679.152 | BP61: =+BN61+BO61 -> 118102.65
A62: 2017 TORRE B | B62: 302 | C62: 15 | E62: =+C62*3 -> 45 | F62: =+C62*$E$93 -> 107346.05 | G62: =+E62*E$92 -> #REF! | H62: =+F62+G62 -> #REF! | I62: 17 | K62: =+I62*$F$1 -> 57.8 | L62: =+I62*$K$93 -> 121658.86 | M62: =+K62*$K$92 -> 117300.38 | N62: =+M62+L62 -> 238959.24 | O62: 10 | Q62: =+O62*$F$1 -> 34 | R62: =+O62*$Q$93 -> 71685.7 | S62: =+Q62*$Q$92 -> 75144.877 | T62: =+S62+R62 -> 146830.58 | U62: 18 | V62: =+U62*$F$1 -> 61.2 | W62: =+U62*$V$93 -> 129034.26 | X62: =+V62*$V$92 -> 143520.68 | Y62: =+X62+W62 -> 272554.94 | Z62: 12 | AA62: =+Z62*$F$1 -> 40.8 | AB62: =+Z62*$AB$93 -> 90128.687 | AC62: =+AA62*$AB$92 -> 83917.292 | AD62: =+AC62+AB62 -> 174045.98 | AE62: 14 | AF62: =+AE62*$F$1 -> 47.6 | AG62: =+AE62*$AF$93 -> 105150.13 | AH62: =+AF62*$AF$92 -> 100312.99 | AI62: =+AH62+AG62 -> 205463.12 | AJ62: 16 | AK62: =+AJ62*$F$1 -> 54.4 | AM62: =+AJ62*$AK$93 -> 118838.14 | AN62: =+AK62*$AK$92 -> 117120.42 | AO62: =+AM62+AN62 -> 235958.56 | AP62: 17 | AQ62: =+AP62*$F$1 -> 57.8 | AS62: =+AP62*$AQ$93 -> 126265.53 | AT62: =+AQ62*$AQ$92 -> 119135.38 | AU62: =+AS62+AT62 -> 245400.9 | AV62: 17 | AW62: =+AV62*$F$1 -> 57.8 | AY62: =+AV62*$AW$93 -> 126268.11 | AZ62: =+AW62*$AW$92 -> 135890.12 | BA62: =+AY62+AZ62 -> 262158.23 | BB62: 15 | BC62: =+BB62*$F$1 -> 51 | BD62: =+BB62*$BC$93 -> 111413.04 | BE62: =+BC62*$BC$92 -> 114331.69 | BF62: =+BD62+BE62 -> 225744.73 | BG62: 10 | BH62: =+BG62*$F$1 -> 34 | BI62: =+BG62*$BH$93 -> 74279.375 | BJ62: =+BH62*$BH$92 -> 71894.514 | BK62: =+BJ62+BI62 -> 146173.89 | BL62: 0 | BM62: =+BL62*$F$1 -> 0 | BN62: =+BL62*$BM$93 -> 0 | BO62: =+BM62*$BM$92 -> 0 | BP62: =+BN62+BO62 -> 0
A63: 2017 TORRE B | B63: 303 | C63: 1 | E63: =+C63*3 -> 3 | F63: =+C63*$E$93 -> 7156.4036 | G63: =+E63*E$92 -> #REF! | H63: =+F63+G63 -> #REF! | I63: 1 | K63: =+I63*$F$1 -> 3.4 | L63: =+I63*$K$93 -> 7156.4036 | M63: =+K63*$K$92 -> 6900.0223 | N63: =+M63+L63 -> 14056.426 | O63: 0 | Q63: =+O63*$F$1 -> 0 | R63: =+O63*$Q$93 -> 0 | S63: =+Q63*$Q$92 -> 0 | T63: =+S63+R63 -> 0 | U63: 1 | V63: =+U63*$F$1 -> 3.4 | W63: =+U63*$V$93 -> 7168.57 | X63: =+V63*$V$92 -> 7973.3711 | Y63: =+X63+W63 -> 15141.941 | Z63: 1 | AA63: =+Z63*$F$1 -> 3.4 | AB63: =+Z63*$AB$93 -> 7510.7239 | AC63: =+AA63*$AB$92 -> 6993.1076 | AD63: =+AC63+AB63 -> 14503.832 | AE63: 0 | AF63: =+AE63*$F$1 -> 0 | AG63: =+AE63*$AF$93 -> 0 | AH63: =+AF63*$AF$92 -> 0 | AI63: =+AH63+AG63 -> 0 | AJ63: 1 | AK63: =+AJ63*$F$1 -> 3.4 | AM63: =+AJ63*$AK$93 -> 7427.3839 | AN63: =+AK63*$AK$92 -> 7320.026 | AO63: =+AM63+AN63 -> 14747.41 | AP63: 1 | AQ63: =+AP63*$F$1 -> 3.4 | AS63: =+AP63*$AQ$93 -> 7427.3839 | AT63: =+AQ63*$AQ$92 -> 7007.9634 | AU63: =+AS63+AT63 -> 14435.347 | AV63: 0 | AW63: =+AV63*$F$1 -> 0 | AY63: =+AV63*$AW$93 -> 0 | AZ63: =+AW63*$AW$92 -> 0 | BA63: =+AY63+AZ63 -> 0 | BB63: 1 | BC63: =+BB63*$F$1 -> 3.4 | BD63: =+BB63*$BC$93 -> 7427.5357 | BE63: =+BC63*$BC$92 -> 7622.1128 | BF63: =+BD63+BE63 -> 15049.648 | BG63: 0 | BH63: =+BG63*$F$1 -> 0 | BI63: =+BG63*$BH$93 -> 0 | BJ63: =+BH63*$BH$92 -> 0 | BK63: =+BJ63+BI63 -> 0 | BL63: 1 | BM63: =+BL63*$F$1 -> 3.4 | BN63: =+BL63*$BM$93 -> 7427.9375 | BO63: =+BM63*$BM$92 -> 7334.894 | BP63: =+BN63+BO63 -> 14762.832
A64: 2017 TORRE B | B64: 401 | C64: 20 | E64: =+C64*3 -> 60 | F64: =+C64*$E$93 -> 143128.07 | G64: =+E64*E$92 -> #REF! | H64: =+F64+G64 -> #REF! | I64: 17 | K64: =+I64*$F$1 -> 57.8 | L64: =+I64*$K$93 -> 121658.86 | M64: =+K64*$K$92 -> 117300.38 | N64: =+M64+L64 -> 238959.24 | O64: 17 | Q64: =+O64*$F$1 -> 57.8 | R64: =+O64*$Q$93 -> 121865.69 | S64: =+Q64*$Q$92 -> 127746.29 | T64: =+S64+R64 -> 249611.98 | U64: 20 | V64: =+U64*$F$1 -> 68 | W64: =+U64*$V$93 -> 143371.4 | X64: =+V64*$V$92 -> 159467.42 | Y64: =+X64+W64 -> 302838.82 | Z64: 6 | AA64: =+Z64*$F$1 -> 20.4 | AB64: =+Z64*$AB$93 -> 45064.343 | AC64: =+AA64*$AB$92 -> 41958.646 | AD64: =+AC64+AB64 -> 87022.989 | AE64: 14 | AF64: =+AE64*$F$1 -> 47.6 | AG64: =+AE64*$AF$93 -> 105150.13 | AH64: =+AF64*$AF$92 -> 100312.99 | AI64: =+AH64+AG64 -> 205463.12 | AJ64: 17 | AK64: =+AJ64*$F$1 -> 57.8 | AM64: =+AJ64*$AK$93 -> 126265.53 | AN64: =+AK64*$AK$92 -> 124440.44 | AO64: =+AM64+AN64 -> 250705.97 | AP64: 16 | AQ64: =+AP64*$F$1 -> 54.4 | AS64: =+AP64*$AQ$93 -> 118838.14 | AT64: =+AQ64*$AQ$92 -> 112127.41 | AU64: =+AS64+AT64 -> 230965.56 | AV64: 18 | AW64: =+AV64*$F$1 -> 61.2 | AY64: =+AV64*$AW$93 -> 133695.64 | AZ64: =+AW64*$AW$92 -> 143883.66 | BA64: =+AY64+AZ64 -> 277579.3 | BB64: 20 | BC64: =+BB64*$F$1 -> 68 | BD64: =+BB64*$BC$93 -> 148550.71 | BE64: =+BC64*$BC$92 -> 152442.26 | BF64: =+BD64+BE64 -> 300992.97 | BG64: 23 | BH64: =+BG64*$F$1 -> 78.2 | BI64: =+BG64*$BH$93 -> 170842.56 | BJ64: =+BH64*$BH$92 -> 165357.38 | BK64: =+BJ64+BI64 -> 336199.94 | BL64: 17 | BM64: =+BL64*$F$1 -> 57.8 | BN64: =+BL64*$BM$93 -> 126274.94 | BO64: =+BM64*$BM$92 -> 124693.2 | BP64: =+BN64+BO64 -> 250968.14
A65: 2017 TORRE B | B65: 402 | C65: 0 | E65: =+C65*3 -> 0 | F65: =+C65*$E$93 -> 0 | G65: =+E65*E$92 -> #REF! | H65: =+F65+G65 -> #REF! | I65: 0 | K65: =+I65*$F$1 -> 0 | L65: =+I65*$K$93 -> 0 | M65: =+K65*$K$92 -> 0 | N65: =+M65+L65 -> 0 | O65: 0 | Q65: =+O65*$F$1 -> 0 | R65: =+O65*$Q$93 -> 0 | S65: =+Q65*$Q$92 -> 0 | T65: =+S65+R65 -> 0 | U65: 0 | V65: =+U65*$F$1 -> 0 | W65: =+U65*$V$93 -> 0 | X65: =+V65*$V$92 -> 0 | Y65: =+X65+W65 -> 0 | Z65: 0 | AA65: =+Z65*$F$1 -> 0 | AB65: =+Z65*$AB$93 -> 0 | AC65: =+AA65*$AB$92 -> 0 | AD65: =+AC65+AB65 -> 0 | AE65: 0 | AF65: =+AE65*$F$1 -> 0 | AG65: =+AE65*$AF$93 -> 0 | AH65: =+AF65*$AF$92 -> 0 | AI65: =+AH65+AG65 -> 0 | AJ65: 0 | AK65: =+AJ65*$F$1 -> 0 | AM65: =+AJ65*$AK$93 -> 0 | AN65: =+AK65*$AK$92 -> 0 | AO65: =+AM65+AN65 -> 0 | AP65: 0 | AQ65: =+AP65*$F$1 -> 0 | AS65: =+AP65*$AQ$93 -> 0 | AT65: =+AQ65*$AQ$92 -> 0 | AU65: =+AS65+AT65 -> 0 | AV65: 0 | AW65: =+AV65*$F$1 -> 0 | AY65: =+AV65*$AW$93 -> 0 | AZ65: =+AW65*$AW$92 -> 0 | BA65: =+AY65+AZ65 -> 0 | BB65: 0 | BC65: =+BB65*$F$1 -> 0 | BD65: =+BB65*$BC$93 -> 0 | BE65: =+BC65*$BC$92 -> 0 | BF65: =+BD65+BE65 -> 0 | BG65: 0 | BH65: =+BG65*$F$1 -> 0 | BI65: =+BG65*$BH$93 -> 0 | BJ65: =+BH65*$BH$92 -> 0 | BK65: =+BJ65+BI65 -> 0 | BL65: 0 | BM65: =+BL65*$F$1 -> 0 | BN65: =+BL65*$BM$93 -> 0 | BO65: =+BM65*$BM$92 -> 0 | BP65: =+BN65+BO65 -> 0
A66: 2017 TORRE B | B66: 403 | C66: 7 | E66: =+C66*3 -> 21 | F66: =+C66*$E$93 -> 50094.825 | G66: =+E66*E$92 -> #REF! | H66: =+F66+G66 -> #REF! | I66: 5 | K66: =+I66*$F$1 -> 17 | L66: =+I66*$K$93 -> 35782.018 | M66: =+K66*$K$92 -> 34500.111 | N66: =+M66+L66 -> 70282.129 | O66: 5 | Q66: =+O66*$F$1 -> 17 | R66: =+O66*$Q$93 -> 35842.85 | S66: =+Q66*$Q$92 -> 37572.438 | T66: =+S66+R66 -> 73415.289 | U66: 9 | V66: =+U66*$F$1 -> 30.6 | W66: =+U66*$V$93 -> 64517.13 | X66: =+V66*$V$92 -> 71760.34 | Y66: =+X66+W66 -> 136277.47 | Z66: 5 | AA66: =+Z66*$F$1 -> 17 | AB66: =+Z66*$AB$93 -> 37553.619 | AC66: =+AA66*$AB$92 -> 34965.538 | AD66: =+AC66+AB66 -> 72519.158 | AE66: 6 | AF66: =+AE66*$F$1 -> 20.4 | AG66: =+AE66*$AF$93 -> 45064.343 | AH66: =+AF66*$AF$92 -> 42991.281 | AI66: =+AH66+AG66 -> 88055.624 | AJ66: 7 | AK66: =+AJ66*$F$1 -> 23.8 | AM66: =+AJ66*$AK$93 -> 51991.687 | AN66: =+AK66*$AK$92 -> 51240.182 | AO66: =+AM66+AN66 -> 103231.87 | AP66: 6 | AQ66: =+AP66*$F$1 -> 20.4 | AS66: =+AP66*$AQ$93 -> 44564.303 | AT66: =+AQ66*$AQ$92 -> 42047.78 | AU66: =+AS66+AT66 -> 86612.084 | AV66: 6 | AW66: =+AV66*$F$1 -> 20.4 | AY66: =+AV66*$AW$93 -> 44565.214 | AZ66: =+AW66*$AW$92 -> 47961.219 | BA66: =+AY66+AZ66 -> 92526.433 | BB66: 6 | BC66: =+BB66*$F$1 -> 20.4 | BD66: =+BB66*$BC$93 -> 44565.214 | BE66: =+BC66*$BC$92 -> 45732.677 | BF66: =+BD66+BE66 -> 90297.891 | BG66: 6 | BH66: =+BG66*$F$1 -> 20.4 | BI66: =+BG66*$BH$93 -> 44567.625 | BJ66: =+BH66*$BH$92 -> 43136.708 | BK66: =+BJ66+BI66 -> 87704.333 | BL66: 7 | BM66: =+BL66*$F$1 -> 23.8 | BN66: =+BL66*$BM$93 -> 51995.562 | BO66: =+BM66*$BM$92 -> 51344.258 | BP66: =+BN66+BO66 -> 103339.82
A67: 2017 TORRE B | B67: 501 | C67: 2 | E67: =+C67*3 -> 6 | F67: =+C67*$E$93 -> 14312.807 | G67: =+E67*E$92 -> #REF! | H67: =+F67+G67 -> #REF! | I67: 4 | K67: =+I67*$F$1 -> 13.6 | L67: =+I67*$K$93 -> 28625.614 | M67: =+K67*$K$92 -> 27600.089 | N67: =+M67+L67 -> 56225.703 | O67: 5 | Q67: =+O67*$F$1 -> 17 | R67: =+O67*$Q$93 -> 35842.85 | S67: =+Q67*$Q$92 -> 37572.438 | T67: =+S67+R67 -> 73415.289 | U67: 5 | V67: =+U67*$F$1 -> 17 | W67: =+U67*$V$93 -> 35842.85 | X67: =+V67*$V$92 -> 39866.855 | Y67: =+X67+W67 -> 75709.706 | Z67: 5 | AA67: =+Z67*$F$1 -> 17 | AB67: =+Z67*$AB$93 -> 37553.619 | AC67: =+AA67*$AB$92 -> 34965.538 | AD67: =+AC67+AB67 -> 72519.158 | AE67: 6 | AF67: =+AE67*$F$1 -> 20.4 | AG67: =+AE67*$AF$93 -> 45064.343 | AH67: =+AF67*$AF$92 -> 42991.281 | AI67: =+AH67+AG67 -> 88055.624 | AJ67: 6 | AK67: =+AJ67*$F$1 -> 20.4 | AM67: =+AJ67*$AK$93 -> 44564.303 | AN67: =+AK67*$AK$92 -> 43920.156 | AO67: =+AM67+AN67 -> 88484.459 | AP67: 6 | AQ67: =+AP67*$F$1 -> 20.4 | AS67: =+AP67*$AQ$93 -> 44564.303 | AT67: =+AQ67*$AQ$92 -> 42047.78 | AU67: =+AS67+AT67 -> 86612.084 | AV67: 6 | AW67: =+AV67*$F$1 -> 20.4 | AY67: =+AV67*$AW$93 -> 44565.214 | AZ67: =+AW67*$AW$92 -> 47961.219 | BA67: =+AY67+AZ67 -> 92526.433 | BB67: 6 | BC67: =+BB67*$F$1 -> 20.4 | BD67: =+BB67*$BC$93 -> 44565.214 | BE67: =+BC67*$BC$92 -> 45732.677 | BF67: =+BD67+BE67 -> 90297.891 | BG67: 3 | BH67: =+BG67*$F$1 -> 10.2 | BI67: =+BG67*$BH$93 -> 22283.812 | BJ67: =+BH67*$BH$92 -> 21568.354 | BK67: =+BJ67+BI67 -> 43852.167 | BL67: 7 | BM67: =+BL67*$F$1 -> 23.8 | BN67: =+BL67*$BM$93 -> 51995.562 | BO67: =+BM67*$BM$92 -> 51344.258 | BP67: =+BN67+BO67 -> 103339.82
A68: 2017 TORRE B | B68: 502 | C68: 3 | E68: =+C68*3 -> 9 | F68: =+C68*$E$93 -> 21469.211 | G68: =+E68*E$92 -> #REF! | H68: =+F68+G68 -> #REF! | I68: 3 | K68: =+I68*$F$1 -> 10.2 | L68: =+I68*$K$93 -> 21469.211 | M68: =+K68*$K$92 -> 20700.067 | N68: =+M68+L68 -> 42169.278 | O68: 4 | Q68: =+O68*$F$1 -> 13.6 | R68: =+O68*$Q$93 -> 28674.28 | S68: =+Q68*$Q$92 -> 30057.951 | T68: =+S68+R68 -> 58732.231 | U68: 4 | V68: =+U68*$F$1 -> 13.6 | W68: =+U68*$V$93 -> 28674.28 | X68: =+V68*$V$92 -> 31893.484 | Y68: =+X68+W68 -> 60567.764 | Z68: 3 | AA68: =+Z68*$F$1 -> 10.2 | AB68: =+Z68*$AB$93 -> 22532.172 | AC68: =+AA68*$AB$92 -> 20979.323 | AD68: =+AC68+AB68 -> 43511.495 | AE68: 5 | AF68: =+AE68*$F$1 -> 17 | AG68: =+AE68*$AF$93 -> 37553.619 | AH68: =+AF68*$AF$92 -> 35826.068 | AI68: =+AH68+AG68 -> 73379.687 | AJ68: 4 | AK68: =+AJ68*$F$1 -> 13.6 | AM68: =+AJ68*$AK$93 -> 29709.536 | AN68: =+AK68*$AK$92 -> 29280.104 | AO68: =+AM68+AN68 -> 58989.64 | AP68: 4 | AQ68: =+AP68*$F$1 -> 13.6 | AS68: =+AP68*$AQ$93 -> 29709.536 | AT68: =+AQ68*$AQ$92 -> 28031.854 | AU68: =+AS68+AT68 -> 57741.389 | AV68: 6 | AW68: =+AV68*$F$1 -> 20.4 | AY68: =+AV68*$AW$93 -> 44565.214 | AZ68: =+AW68*$AW$92 -> 47961.219 | BA68: =+AY68+AZ68 -> 92526.433 | BB68: 5 | BC68: =+BB68*$F$1 -> 17 | BD68: =+BB68*$BC$93 -> 37137.678 | BE68: =+BC68*$BC$92 -> 38110.564 | BF68: =+BD68+BE68 -> 75248.242 | BG68: 5 | BH68: =+BG68*$F$1 -> 17 | BI68: =+BG68*$BH$93 -> 37139.688 | BJ68: =+BH68*$BH$92 -> 35947.257 | BK68: =+BJ68+BI68 -> 73086.944 | BL68: 6 | BM68: =+BL68*$F$1 -> 20.4 | BN68: =+BL68*$BM$93 -> 44567.625 | BO68: =+BM68*$BM$92 -> 44009.364 | BP68: =+BN68+BO68 -> 88576.989
... A88: 2017 TORRE B | B88: 1302 | C88: 6 | E88: =+C88*3 -> 18 | F88: =+C88*$E$93 -> 42938.421 | G88: =+E88*E$92 -> #REF! | H88: =+F88+G88 -> #REF! | I88: 1 | K88: =+I88*$F$1 -> 3.4 | L88: =+I88*$K$93 -> 7156.4036 | M88: =+K88*$K$92 -> 6900.0223 | N88: =+M88+L88 -> 14056.426 | O88: 8 | Q88: =+O88*$F$1 -> 27.2 | R88: =+O88*$Q$93 -> 57348.56 | S88: =+Q88*$Q$92 -> 60115.901 | T88: =+S88+R88 -> 117464.46 | U88: 8 | V88: =+U88*$F$1 -> 27.2 | W88: =+U88*$V$93 -> 57348.56 | X88: =+V88*$V$92 -> 63786.969 | Y88: =+X88+W88 -> 121135.53 | Z88: 4 | AA88: =+Z88*$F$1 -> 13.6 | AB88: =+Z88*$AB$93 -> 30042.896 | AC88: =+AA88*$AB$92 -> 27972.431 | AD88: =+AC88+AB88 -> 58015.326 | AE88: 7 | AF88: =+AE88*$F$1 -> 23.8 | AG88: =+AE88*$AF$93 -> 52575.067 | AH88: =+AF88*$AF$92 -> 50156.495 | AI88: =+AH88+AG88 -> 102731.56 | AJ88: 6 | AK88: =+AJ88*$F$1 -> 20.4 | AM88: =+AJ88*$AK$93 -> 44564.303 | AN88: =+AK88*$AK$92 -> 43920.156 | AO88: =+AM88+AN88 -> 88484.459 | AP88: 5 | AQ88: =+AP88*$F$1 -> 17 | AS88: =+AP88*$AQ$93 -> 37136.919 | AT88: =+AQ88*$AQ$92 -> 35039.817 | AU88: =+AS88+AT88 -> 72176.736 | AV88: 7 | AW88: =+AV88*$F$1 -> 23.8 | AY88: =+AV88*$AW$93 -> 51992.75 | AZ88: =+AW88*$AW$92 -> 55954.755 | BA88: =+AY88+AZ88 -> 107947.5 | BB88: 8 | BC88: =+BB88*$F$1 -> 27.2 | BD88: =+BB88*$BC$93 -> 59420.285 | BE88: =+BC88*$BC$92 -> 60976.902 | BF88: =+BD88+BE88 -> 120397.19 | BG88: 12 | BH88: =+BG88*$F$1 -> 40.8 | BI88: =+BG88*$BH$93 -> 89135.25 | BJ88: =+BH88*$BH$92 -> 86273.417 | BK88: =+BJ88+BI88 -> 175408.67 | BL88: 0 | BM88: =+BL88*$F$1 -> 0 | BN88: =+BL88*$BM$93 -> 0 | BO88: =+BM88*$BM$92 -> 0 | BP88: =+BN88+BO88 -> 0
...

Sheet DETERMINACIÓN M3 GAS
A2: 2022 | N2: 2023 | AA2: 2024 | AN2: 2025
B5: LECTURAS INSTALACION MEDIDORES COBRO CALDERAS | O5: LECTURAS INSTALACION MEDIDORES COBRO CALDERAS | AB5: LECTURAS INSTALACION MEDIDORES COBRO CALDERAS | AO5: LECTURAS INSTALACION MEDIDORES COBRO CALDERAS
B6: FECHAS | C6: MEDIDOR RED AGUA EEAB | D6: NUEVO MEDIDOR AGUA ZONAS COMUNES M3 | E6: NUEVO MEDIDOR AGUA DUCHAS M3 | F6: NUEVO MEDIDOR GAS ZONAS HUMEDAS M3 | O6: FECHAS | P6: MEDIDOR RED AGUA EEAB | Q6: NUEVO MEDIDOR AGUA ZONAS COMUNES M3 | R6: NUEVO MEDIDOR AGUA DUCHAS M3 | S6: NUEVO MEDIDOR GAS ZONAS HUMEDAS M3 | AB6: FECHAS | AC6: MEDIDOR RED AGUA EEAB | AD6: NUEVO MEDIDOR AGUA ZONAS COMUNES M3 | AE6: NUEVO MEDIDOR AGUA DUCHAS M3 | AF6: NUEVO MEDIDOR GAS ZONAS HUMEDAS M3 | AO6: FECHAS | AP6: MEDIDOR RED AGUA EEAB | AQ6: NUEVO MEDIDOR AGUA ZONAS COMUNES M3 | AR6: NUEVO MEDIDOR AGUA DUCHAS M3 | AS6: NUEVO MEDIDOR GAS ZONAS HUMEDAS M3
B7: 44541 | C7: 118462 | D7: 2.4227 | E7: 0 | F7: 45.011 | O7: 44886 | P7: 125187 | Q7: 601.3755 | R7: 63 | S7: 10446.908 | AB7: 45279 | AC7: 132044 | AD7: 1317.03 | AE7: 131 | AF7: 22604.798 | AO7: 45678 | AP7: 139194 | AQ7: 1960.4629 | AR7: 183 | AS7: 36363.821
B8: 44542 | C8: 118481 | D8: 3.034 | E8: 0 | F8: 79.153 | O8: 44887 | P8: 125210 | Q8: 602.6786 | R8: 63 | S8: 10485.826 | AB8: 45280 | AC8: 132063 | AD8: 1318.58 | AE8: 131 | AF8: 22630.995 | AO8: 45679 | AP8: 139212 | AQ8: 1961.7774 | AR8: 183 | AS8: 36416.302
B9: 44543 | C9: 118506 | D9: 5.0895 | E9: 0 | F9: 85.002 | O9: 44888 | P9: 125218 | Q9: 603.9089 | R9: 63 | S9: 10513.251 | U9: 21 DE NOVIEMBRE A DICIEMBRE 19 | AB9: 45281 | AC9: 132083 | AD9: 1319.95 | AE9: 131 | AF9: 22684.374 | AH9: 19 DE DICIEMBRE A ENERO 20 | AO9: 45680 | AP9: 139231 | AQ9: 1964.0417 | AR9: 183 | AS9: 36416.312 | AU9: 21 DE ENERO A FEBRERO 19
B10: 44544 | C10: 118531 | D10: 6.8829 | E10: 0 | F10: 139.141 | O10: 44889 | P10: 125243 | Q10: 604.8829 | R10: 63 | S10: 10552.575 | U10: TORRES | V10: TORRES | W10: AREAS COMUNES | X10: CALDERAS TORRES | AB10: 45282 | AC10: 132101 | AD10: 1322 | AE10: 131 | AF10: 22740.362 | AH10: TORRES | AI10: TORRES | AJ10: AREAS COMUNES | AK10: CALDERAS TORRES | AO10: 45681 | AP10: 139249 | AQ10: 1965.2826 | AR10: 183 | AS10: 36487.641 | AU10: TORRES | AV10: TORRES | AW10: AREAS COMUNES | AX10: CALDERAS TORRES
B11: 44545 | C11: 118555 | D11: 8.4556 | E11: 0 | F11: 178.329 | O11: 44890 | P11: 125272 | Q11: 607.5774 | R11: 64 | S11: 10587.837 | U11: GAS TORRE A | V11: =+'Vr M3 DE GAS'!AV18 -> 2122 | W11: =+S35-S7 -> 1031.711 | X11: =+V11-W11 -> 1090.289 | Y11: =+X11-K324 -> -229.136 | Z11: =+Y11/K324 -> -0.17366353 | AB11: 45283 | AC11: 132117 | AD11: 1323.23 | AE11: 131 | AF11: 22751.153 | AH11: GAS TORRE A | AI11: ='Vr M3 DE GAS'!BN7 -> 1729 | AJ11: =+AF39-AF7 -> 849.131 | AK11: =+AI11-AJ11 -> 879.869 | AL11: =+AK11-Z324 -> 879.869 | AM11: =+AL11/Y383 -> 1.048298 | AO11: 45682 | AP11: 139263 | AQ11: 1966.2089 | AR11: 183 | AS11: 36540.855 | AU11: GAS TORRE A | AV11: ='Vr M3 DE GAS'!BV8 -> 1968 | AW11: =+AS36-AS7 -> 1082.294 | AX11: =+AV11-AW11 -> 885.706 | AY11: =+AX11-AM324 -> 885.706 | AZ11: =+AY11/AL383 -> 0.95152386
B12: 44546 | C12: 118575 | D12: 9.9401 | E12: 0 | F12: 219.451 | O12: 44891 | P12: 125294 | Q12: 608.6983 | R12: 64 | S12: 10622.268 | U12: GAS TORRE B | V12: =+'Vr M3 DE GAS'!AV36 -> 1383 | X12: =+V12-W12 -> 1383 | Y12: =+X12-K325 -> -172 | Z12: =+Y12/K325 -> -0.11061093 | AB12: 45284 | AC12: 132130 | AD12: 1323.81 | AE12: 131 | AF12: 22765.59 | AH12: GAS TORRE B | AI12: ='Vr M3 DE GAS'!BN25 -> 1077 | AK12: =+AI12-AJ12 -> 1077 | AL12: =+AK12-Z325 -> 1077 | AM12: =+AL12/Y384 -> 1.0385728 | AO12: 45683 | AP12: 139276 | AQ12: 1967.0829 | AR12: 184 | AS12: 36576.872 | AU12: GAS TORRE B | AV12: ='Vr M3 DE GAS'!BV26 -> 908 | AX12: =+AV12-AW12 -> 908 | AY12: =+AX12-AM325 -> 908 | AZ12: =+AY12/AL384 -> 1.0835322
B13: 44547 | C13: 118597 | D13: 10.6154 | E13: 0 | F13: 244.966 | O13: 44892 | P13: 125314 | Q13: 609.7777 | R13: 64 | S13: 10662.612 | U13: GAS TORRE C | V13: =+'Vr M3 DE GAS'!AV54 -> 1371 | X13: =+V13-W13 -> 1371 | Y13: =+X13-K326 -> -205 | Z13: =+Y13/K326 -> -0.13007614 | AB13: 45285 | AC13: 132140 | AD13: 1324.29 | AE13: 131 | AF13: 22787.967 | AH13: GAS TORRE C | AI13: ='Vr M3 DE GAS'!BN43 -> 1221 | AK13: =+AI13-AJ13 -> 1221 | AL13: =+AK13-Z326 -> 1221 | AM13: =+AL13/Y385 -> 1.1009919 | AO13: 45684 | AP13: 139295 | AQ13: 1970.0809 | AR13: 184 | AS13: 36585.624 | AU13: GAS TORRE C | AV13: ='Vr M3 DE GAS'!BV44 -> 810 | AX13: =+AV13-AW13 -> 810 | AY13: =+AX13-AM326 -> 810 | AZ13: =+AY13/AL385 -> 0.97944377
B14: 44548 | C14: 118621 | D14: 13.3267 | E14: 0 | F14: 292.638 | O14: 44893 | P14: 125343 | Q14: 612.25 | R14: 64 | S14: 10685.358 | AB14: 45286 | AC14: 132155 | AD14: 1326.08 | AE14: 131 | AF14: 22827.756 | AO14: 45685 | AP14: 139313 | AQ14: 1971.642 | AR14: 184 | AS14: 36612.483
B15: 44549 | C15: 118635 | D15: 14.1891 | E15: 0 | F15: 348.914 | O15: 44894 | P15: 125367 | Q15: 613.6895 | R15: 64 | S15: 10715.619 | U15: TOTAL EDIFICIO | V15: =SUM(V11:V14) -> 4876 | W15: =+W11 -> 1031.711 | X15: =SUM(X11:X14) -> 3844.289 | Y15: =+X15-K328 -> -606.136 | Z15: =+Y15/K328 -> -0.13619733 | AB15: 45287 | AC15: 132169 | AD15: 1328.59 | AE15: 131 | AF15: 22869.339 | AH15: TOTAL EDIFICIO | AI15: =SUM(AI11:AI14) -> 4027 | AJ15: =+AJ11 -> 849.131 | AK15: =SUM(AK11:AK14) -> 3177.869 | AL15: =+AK15-Z328 -> 3177.869 | AM15: =+AL15/X387 -> 1.0644947 | AO15: 45686 | AP15: 139332 | AQ15: 1974.3663 | AR15: 184 | AS15: 36685.713 | AU15: TOTAL EDIFICIO | AV15: =SUM(AV11:AV14) -> 3686 | AW15: =+AW11 -> 1082.294 | AX15: =SUM(AX11:AX14) -> 2603.706 | AY15: =+AX1-AM328 -> 0 | AZ15: =+AY15/AK387 -> 0
B16: 44550 | C16: 118655 | D16: 16.6413 | E16: 0 | F16: 354.542 | H16: ANALISIS PARA GAS A PAGAR EN FEBRERO | O16: 44895 | P16: 125392 | Q16: 614.9698 | R16: 64 | S16: 10752.461 | AB16: 45288 | AC16: 132182 | AD16: 1329.54 | AE16: 131 | AF16: 22884.108 | AO16: 45687 | AP16: 139348 | AQ16: 1975.4131 | AR16: 184 | AS16: 36708.914
B17: 44551 | C17: 118676 | D17: 18.661 | E17: 0 | F17: 396.057 | H17: 18 DIC A 21 DE ENERO | O17: 44896 | P17: 125420 | Q17: 615.968 | R17: 64 | S17: 10785.894 | AB17: 45289 | AC17: 132194 | AD17: 1330.26 | AE17: 131 | AF17: 22909.595 | AO17: 45688 | AP17: 139367 | AQ17: 1977.5527 | AR17: 185 | AS17: 36714.816
B18: 44552 | C18: 118695 | D18: 20.2081 | E18: 0 | F18: 432.577 | I18: TORRES | J18: AREAS COMUNES | K18: TORRES | O18: 44897 | P18: 125470 | Q18: 620.2113 | R18: 64 | S18: 10906.983 | U18: AGUA | AB18: 45290 | AC18: 132204 | AD18: 1331.91 | AE18: 131 | AF18: 22925.323 | AH18: AGUA | AO18: 45689 | AP18: 139383 | AQ18: 1978.444 | AR18: 185 | AS18: 36746.749 | AU18: AGUA
B19: 44553 | C19: 118710 | D19: 21.7313 | E19: 1 | F19: 460.224 | H19: TORRE A | I19: =+'Vr M3 DE GAS'!AV7 -> 2307 | J19: =+F48-F14 -> 1284.202 | K19: =+I19-J19 -> 1022.798 | O19: 44898 | P19: 125475 | Q19: 620.5943 | R19: 65 | S19: 10906.985 | AB19: 45291 | AC19: 132213 | AD19: 1332.5 | AE19: 131 | AF19: 22925.369 | AO19: 45690 | AP19: 139397 | AQ19: 1978.8266 | AR19: 185 | AS19: 39779.466
B20: 44554 | C20: 118725 | D20: 22.2733 | E20: 1 | F20: 493.064 | H20: TORRE B | I20: =+'Vr M3 DE GAS'!AV25 -> 1079 | K20: =+I20-J20 -> 1079 | O20: 44899 | P20: 125491 | Q20: 621.8484 | R20: 65 | S20: 10949.421 | U20: TOTAL CALLEJA | V20: =+P35-P7 -> 654 | AB20: 45292 | AC20: 132218 | AD20: 1332.6608 | AE20: 131 | AF20: 22925.372 | AH20: TOTAL CALLEJA | AI20: =+AC39-AC7 -> 456 | AO20: 45691 | AP20: 139419 | AQ20: 1982.5028 | AR20: 185 | AS20: 36779.486 | AU20: TOTAL CALLEJA | AV20: =+AP36-AP7 -> 511
B21: 44555 | C21: 118734 | D21: 22.6903 | E21: 1 | F21: 521.05 | H21: TORRE C | I21: =+'Vr M3 DE GAS'!AV43 -> 1339 | K21: =+I21-J21 -> 1339 | O21: 44900 | P21: 125519 | Q21: 624.1462 | R21: 65 | S21: 10984.678 | U21: AREAS COMUNES | V21: =+Q35-Q7 -> 43.0667 | AB21: 45293 | AC21: 132227 | AD21: 1333.9341 | AE21: 131 | AF21: 22978.77 | AH21: AREAS COMUNES | AI21: =+AD39-AD7 -> 40.0947 | AO21: 45692 | AP21: 139431 | AQ21: 1983.974 | AR21: 185 | AS21: 36836.739 | AU21: AREAS COMUNES | AV21: =+AQ36-AQ7 -> 47.7836
B22: 44556 | C22: 118745 | D22: 24.1576 | E22: 1 | F22: 579.153 | O22: 44901 | P22: 125543 | Q22: 625.2522 | R22: 65 | S22: 11010.497 | U22: APARTAMENTOS | V22: =+V20-V21 -> 610.9333 | AB22: 45294 | AC22: 132237 | AD22: 1334.5338 | AE22: 131 | AF22: 23012.847 | AH22: APARTAMENTOS | AI22: =+AI20-AI21 -> 415.9053 | AO22: 45693 | AP22: 139459 | AQ22: 1986.5423 | AR22: 185 | AS22: 36877.205 | AU22: APARTAMENTOS | AV22: =+AV20-AV21 -> 463.2164
B23: 44557 | C23: 118762 | D23: 27.133 | E23: 2 | F23: 580.414 | I23: =SUM(I19:I22) -> 4725 | K23: =+K19+K20+K21 -> 3440.798 | O23: 44902 | P23: 125569 | Q23: 626.9417 | R23: 65 | S23: 11051.8 | AB23: 45295 | AC23: 132247 | AD23: 1335.2617 | AE23: 131 | AF23: 23049.066 | AO23: 45694 | AP23: 139476 | AQ23: 1987.74 | AR23: 185 | AS23: 36894.36
B24: 44558 | C24: 118777 | D24: 29.7512 | E24: 2 | F24: 644.272 | O24: 44903 | P24: 125586 | Q24: 627.5712 | R24: 66 | S24: 11095.042 | AB24: 45296 | AC24: 132259 | AD24: 1337.0141 | AE24: 131 | AF24: 23070.798 | AO24: 45695 | AP24: 139496 | AQ24: 1989.7745 | AR24: 185 | AS24: 36921.906
B25: 44559 | C25: 118789 | D25: 30.5447 | E25: 2 | F25: 682.621 | O25: 44904 | P25: 125609 | Q25: 629.2467 | R25: 66 | S25: 11133.708 | U25: SE CONSUMIERON | V25: =+V22 -> 610.9333 | W25: DE AGUA CALIENTE | Y25: =+V25-I338 -> 58.2199 | Z25: =+Y25/I338 -> 0.1053347 | AB25: 45297 | AC25: 132268 | AD25: 1337.6614 | AE25: 131 | AF25: 23090.685 | AH25: SE CONSUMIERON | AI25: =+AI22 -> 415.9053 | AJ25: DE AGUA CALIENTE | AL25: =AI25/V397-100% -> -0.17150339 | AO25: 45696 | AP25: 139511 | AQ25: 1990.536 | AR25: 186 | AS25: 36982.803 | AU25: SE CONSUMIERON | AV25: =+AV22 -> 463.2164 | AW25: DE AGUA CALIENTE | AY25: =AV25/AI397-1 -> -0.010221368
B26: 44560 | C26: 118801 | D26: 31.426 | E26: 3 | F26: 727.28 | H26: CONSUMO DE AGUA ENTRE EL 21 DE ENERO Y EL 18 DE FEBRERO | O26: 44905 | P26: 125628 | Q26: 630.2533 | R26: 66 | S26: 11167.212 | AB26: 45298 | AC26: 132279 | AD26: 1338.0929 | AE26: 131 | AF26: 23090.772 | AO26: 45697 | AP26: 139525 | AQ26: 1990.6969 | AR26: 186 | AS26: 37040.125
B27: 44561 | C27: 118809 | D27: 34.2909 | E27: 3 | F27: 747.082 | O27: 44906 | P27: 125646 | Q27: 630.9788 | R27: 66 | S27: 11231.902 | U27: SE CONSUMIO DE GAS | V27: =+X15 -> 3844.289 | W27: M3 EN CALDERAS | Y27: =+V27-I340 -> -606.136 | Z27: =+Y27/I340 -> -0.13619733 | AB27: 45299 | AC27: 132293 | AD27: 1338.3377 | AE27: 131 | AF27: 23152.989 | AH27: SE CONSUMIO DE GAS | AI27: =+AK15 -> 3177.869 | AJ27: M3 EN CALDERAS | AL27: =AI27/V399-100% -> 0.064494691 | AO27: 45698 | AP27: 139545 | AQ27: 1993.5854 | AR27: 186 | AS27: 37050.288 | AU27: SE CONSUMIO DE GAS | AV27: =+AX15 -> 2603.706 | AW27: M3 EN CALDERAS | AY27: =AV27/AI399-1 -> 0.0030344834
B28: 44562 | C28: 118824 | D28: 34.8801 | E28: 3 | F28: 792.934 | H28: TOTAL CALLEJA | I28: =+C48-C14 -> 577 | O28: 44907 | P28: 125673 | Q28: 633.4956 | R28: 66 | S28: 11264.519 | AB28: 45300 | AC28: 132307 | AD28: 1340.2743 | AE28: 131 | AF28: 23157.448 | AO28: 45699 | AP28: 139562 | AQ28: 1994.4859 | AR28: 186 | AS28: 37064.816
B29: 44563 | C29: 118836 | D29: 38.4873 | E29: 3 | F29: 812.753 | H29: AREAS COMUNES | I29: =+D48-D14 -> 75.8283 | O29: 44908 | P29: 125700 | Q29: 635.1252 | R29: 67 | S29: 11281.02 | U29: SE REQUIERIO | V29: =+V27/V25 -> 6.2924856 | W29: M3 DE GAS PARA CALENTAR 1 M3 DE AGUA | AB29: 45301 | AC29: 132323 | AD29: 1341.1288 | AE29: 131 | AF29: 23203.473 | AH29: SE REQUIERIO | AI29: =+AI27/AI25 -> 7.6408476 | AJ29: M3 DE GAS PARA CALENTAR 1 M3 DE AGUA | AO29: 45700 | AP29: 139581 | AQ29: 1996.47 | AR29: 186 | AS29: 37147.822 | AU29: SE REQUIERIO | AV29: =+AV27/AV25 -> 5.6209279 | AW29: M3 DE GAS PARA CALENTAR 1 M3 DE AGUA
B30: 44564 | C30: 118849 | D30: 39.5116 | E30: 3 | F30: 843.103 | H30: APARTAMENTOS | I30: =+I28-I29 -> 501.1717 | O30: 44909 | P30: 125725 | Q30: 636.7384 | R30: 67 | S30: 11323.808 | AB30: 45302 | AC30: 132342 | AD30: 1342.4597 | AE30: 131 | AF30: 23245.002 | AO30: 45701 | AP30: 139599 | AQ30: 1997.8749 | AR30: 186 | AS30: 37193.721
B31: 44565 | C31: 118862 | D31: 41.433 | E31: 3 | F31: 877 | O31: 44910 | P31: 125751 | Q31: 638.4419 | R31: 67 | S31: 11370.328 | AB31: 45303 | AC31: 132361 | AD31: 1345.4893 | AE31: 132 | AF31: 23265.322 | AO31: 45702 | AP31: 139621 | AQ31: 2001.4149 | AR31: 187 | AS31: 37288.912
B32: 44566 | C32: 118891 | D32: 54.8007 | E32: 3 | F32: 925.548 | O32: 44911 | P32: 125778 | Q32: 640.4033 | R32: 67 | S32: 11400.502 | AB32: 45304 | AC32: 132376 | AD32: 1345.8289 | AE32: 132 | AF32: 23297.636 | AO32: 45703 | AP32: 139636 | AQ32: 2002.3015 | AR32: 187 | AS32: 37335.397
B33: 44567 | C33: 118907 | D33: 57.7752 | E33: 3 | F33: 964.967 | H33: SE CONSUMIERON | I33: =+I30 -> 501.1717 | J33: DE AGUA CALIENTE | O33: 44912 | P33: 125801 | Q33: 641.7631 | R33: 68 | S33: 11437.736 | AB33: 45305 | AC33: 132390 | AD33: 1346.2573 | AE33: 132 | AF33: 23325.355 | AO33: 45704 | AP33: 139650 | AQ33: 2003.2219 | AR33: 187 | AS33: 37353.338
